[2024-01-22 15:35:21,044][ThreadPoolExecutor-1_0:19912][task_id:apscheduler.executors.default][base.py:131][ERROR][Job "HttpDao.run_test_suite (trigger: cron[month='*', day='*', day_of_week='*', hour='*', minute='*'], next run at: 2024-01-22 15:36:00 CST)" raised an exception]
Traceback (most recent call last):
  File "C:\Users\86135\AppData\Local\Programs\Python\Python311\Lib\site-packages\redis\connection.py", line 698, in connect
    sock = self.retry.call_with_retry(
           ^^^^^^^^^^^^^^^^^^^^^^^^^^^
  File "C:\Users\86135\AppData\Local\Programs\Python\Python311\Lib\site-packages\redis\retry.py", line 51, in call_with_retry
    raise error
  File "C:\Users\86135\AppData\Local\Programs\Python\Python311\Lib\site-packages\redis\retry.py", line 46, in call_with_retry
    return do()
           ^^^^
  File "C:\Users\86135\AppData\Local\Programs\Python\Python311\Lib\site-packages\redis\connection.py", line 699, in <lambda>
    lambda: self._connect(), lambda error: self.disconnect(error)
            ^^^^^^^^^^^^^^^
  File "C:\Users\86135\AppData\Local\Programs\Python\Python311\Lib\site-packages\redis\connection.py", line 987, in _connect
    raise err
  File "C:\Users\86135\AppData\Local\Programs\Python\Python311\Lib\site-packages\redis\connection.py", line 975, in _connect
    sock.connect(socket_address)
TimeoutError: [WinError 10060] 由于连接方在一段时间后没有正确答复或连接的主机没有反应，连接尝试失败。

During handling of the above exception, another exception occurred:

Traceback (most recent call last):
  File "C:\Users\86135\AppData\Local\Programs\Python\Python311\Lib\site-packages\apscheduler\executors\base.py", line 125, in run_job
    retval = job.func(*job.args, **job.kwargs)
             ^^^^^^^^^^^^^^^^^^^^^^^^^^^^^^^^^
  File "C:\Users\86135\Desktop\EasyPost\backend\utils\decorator.py", line 34, in wrapper
    with RedLock(f"distributed_lock:{func.__name__}:{key}:{str(args)}",
  File "C:\Users\86135\AppData\Local\Programs\Python\Python311\Lib\site-packages\redlock\lock.py", line 116, in __enter__
    if not self.acquire():
           ^^^^^^^^^^^^^^
  File "C:\Users\86135\AppData\Local\Programs\Python\Python311\Lib\site-packages\redlock\lock.py", line 154, in acquire
    if self.acquire_node(node):
       ^^^^^^^^^^^^^^^^^^^^^^^
  File "C:\Users\86135\AppData\Local\Programs\Python\Python311\Lib\site-packages\redlock\lock.py", line 134, in acquire_node
    return node.set(self.resource, self.lock_key, nx=True, px=self.ttl)
           ^^^^^^^^^^^^^^^^^^^^^^^^^^^^^^^^^^^^^^^^^^^^^^^^^^^^^^^^^^^^
  File "C:\Users\86135\AppData\Local\Programs\Python\Python311\Lib\site-packages\redis\commands\core.py", line 2302, in set
    return self.execute_command("SET", *pieces, **options)
           ^^^^^^^^^^^^^^^^^^^^^^^^^^^^^^^^^^^^^^^^^^^^^^^
  File "C:\Users\86135\AppData\Local\Programs\Python\Python311\Lib\site-packages\redis\client.py", line 1255, in execute_command
    conn = self.connection or pool.get_connection(command_name, **options)
                              ^^^^^^^^^^^^^^^^^^^^^^^^^^^^^^^^^^^^^^^^^^^^
  File "C:\Users\86135\AppData\Local\Programs\Python\Python311\Lib\site-packages\redis\connection.py", line 1442, in get_connection
    connection.connect()
  File "C:\Users\86135\AppData\Local\Programs\Python\Python311\Lib\site-packages\redis\connection.py", line 702, in connect
    raise TimeoutError("Timeout connecting to server")
redis.exceptions.TimeoutError: Timeout connecting to server
[2024-01-23 10:38:00,059][ThreadPoolExecutor-1_0:16664][task_id:apscheduler.executors.default][base.py:131][ERROR][Job "HttpDao.run_test_suite (trigger: cron[month='*', day='*', day_of_week='*', hour='*', minute='*'], next run at: 2024-01-23 10:39:00 CST)" raised an exception]
Traceback (most recent call last):
  File "C:\Users\86135\Desktop\EasyPost\backend\api\dao\https.py", line 401, in run_test_suite
    result = run_test(case_data)
             ^^^^^^^^^^^^^^^^^^^
  File "C:\Users\86135\Desktop\EasyPost\backend\core\engine\session_runner.py", line 44, in run_test
    suite = GenerateCase().data_to_suite(case_data)
            ^^^^^^^^^^^^^^^^^^^^^^^^^^^^^^^^^^^^^^^
  File "C:\Users\86135\Desktop\EasyPost\backend\core\engine\generate.py", line 28, in data_to_suite
    self.add_test(item, load, suite)
  File "C:\Users\86135\Desktop\EasyPost\backend\core\engine\generate.py", line 36, in add_test
    cls = self.create_test_class(item)
          ^^^^^^^^^^^^^^^^^^^^^^^^^^^^
  File "C:\Users\86135\Desktop\EasyPost\backend\core\engine\generate.py", line 50, in create_test_class
    self.create_case_content(cls, collections)
  File "C:\Users\86135\Desktop\EasyPost\backend\core\engine\generate.py", line 97, in create_case_content
    self.controller.loop(loop_count, cls, test_name, new_test_func)
  File "C:\Users\86135\Desktop\EasyPost\backend\core\engine\base.py", line 61, in loop
    self.info_log('用例第{}次循环\n'.format(c + 1))
  File "C:\Users\86135\Desktop\EasyPost\backend\core\engine\log.py", line 38, in info_log
    self.save_log(message, 'INFO')
  File "C:\Users\86135\Desktop\EasyPost\backend\core\engine\log.py", line 13, in save_log
    print(info)
OSError: [Errno 22] Invalid argument

During handling of the above exception, another exception occurred:

Traceback (most recent call last):
  File "C:\Users\86135\AppData\Local\Programs\Python\Python311\Lib\site-packages\apscheduler\executors\base.py", line 125, in run_job
    retval = job.func(*job.args, **job.kwargs)
             ^^^^^^^^^^^^^^^^^^^^^^^^^^^^^^^^^
  File "C:\Users\86135\Desktop\EasyPost\backend\api\dao\https.py", line 404, in run_test_suite
    raise Exception(f"调试测试计划失败: {e}")
Exception: 调试测试计划失败: [Errno 22] Invalid argument
[2024-01-23 10:39:00,052][ThreadPoolExecutor-1_0:16664][task_id:apscheduler.executors.default][base.py:131][ERROR][Job "HttpDao.run_test_suite (trigger: cron[month='*', day='*', day_of_week='*', hour='*', minute='*'], next run at: 2024-01-23 10:40:00 CST)" raised an exception]
Traceback (most recent call last):
  File "C:\Users\86135\Desktop\EasyPost\backend\api\dao\https.py", line 401, in run_test_suite
    result = run_test(case_data)
             ^^^^^^^^^^^^^^^^^^^
  File "C:\Users\86135\Desktop\EasyPost\backend\core\engine\session_runner.py", line 44, in run_test
    suite = GenerateCase().data_to_suite(case_data)
            ^^^^^^^^^^^^^^^^^^^^^^^^^^^^^^^^^^^^^^^
  File "C:\Users\86135\Desktop\EasyPost\backend\core\engine\generate.py", line 28, in data_to_suite
    self.add_test(item, load, suite)
  File "C:\Users\86135\Desktop\EasyPost\backend\core\engine\generate.py", line 36, in add_test
    cls = self.create_test_class(item)
          ^^^^^^^^^^^^^^^^^^^^^^^^^^^^
  File "C:\Users\86135\Desktop\EasyPost\backend\core\engine\generate.py", line 50, in create_test_class
    self.create_case_content(cls, collections)
  File "C:\Users\86135\Desktop\EasyPost\backend\core\engine\generate.py", line 97, in create_case_content
    self.controller.loop(loop_count, cls, test_name, new_test_func)
  File "C:\Users\86135\Desktop\EasyPost\backend\core\engine\base.py", line 61, in loop
    self.info_log('用例第{}次循环\n'.format(c + 1))
  File "C:\Users\86135\Desktop\EasyPost\backend\core\engine\log.py", line 38, in info_log
    self.save_log(message, 'INFO')
  File "C:\Users\86135\Desktop\EasyPost\backend\core\engine\log.py", line 13, in save_log
    print(info)
OSError: [Errno 22] Invalid argument

During handling of the above exception, another exception occurred:

Traceback (most recent call last):
  File "C:\Users\86135\AppData\Local\Programs\Python\Python311\Lib\site-packages\apscheduler\executors\base.py", line 125, in run_job
    retval = job.func(*job.args, **job.kwargs)
             ^^^^^^^^^^^^^^^^^^^^^^^^^^^^^^^^^
  File "C:\Users\86135\Desktop\EasyPost\backend\api\dao\https.py", line 404, in run_test_suite
    raise Exception(f"调试测试计划失败: {e}")
Exception: 调试测试计划失败: [Errno 22] Invalid argument
[2024-01-23 10:40:00,069][ThreadPoolExecutor-1_0:16664][task_id:apscheduler.executors.default][base.py:131][ERROR][Job "HttpDao.run_test_suite (trigger: cron[month='*', day='*', day_of_week='*', hour='*', minute='*'], next run at: 2024-01-23 10:41:00 CST)" raised an exception]
Traceback (most recent call last):
  File "C:\Users\86135\Desktop\EasyPost\backend\api\dao\https.py", line 401, in run_test_suite
    result = run_test(case_data)
             ^^^^^^^^^^^^^^^^^^^
  File "C:\Users\86135\Desktop\EasyPost\backend\core\engine\session_runner.py", line 44, in run_test
    suite = GenerateCase().data_to_suite(case_data)
            ^^^^^^^^^^^^^^^^^^^^^^^^^^^^^^^^^^^^^^^
  File "C:\Users\86135\Desktop\EasyPost\backend\core\engine\generate.py", line 28, in data_to_suite
    self.add_test(item, load, suite)
  File "C:\Users\86135\Desktop\EasyPost\backend\core\engine\generate.py", line 36, in add_test
    cls = self.create_test_class(item)
          ^^^^^^^^^^^^^^^^^^^^^^^^^^^^
  File "C:\Users\86135\Desktop\EasyPost\backend\core\engine\generate.py", line 50, in create_test_class
    self.create_case_content(cls, collections)
  File "C:\Users\86135\Desktop\EasyPost\backend\core\engine\generate.py", line 97, in create_case_content
    self.controller.loop(loop_count, cls, test_name, new_test_func)
  File "C:\Users\86135\Desktop\EasyPost\backend\core\engine\base.py", line 61, in loop
    self.info_log('用例第{}次循环\n'.format(c + 1))
  File "C:\Users\86135\Desktop\EasyPost\backend\core\engine\log.py", line 38, in info_log
    self.save_log(message, 'INFO')
  File "C:\Users\86135\Desktop\EasyPost\backend\core\engine\log.py", line 13, in save_log
    print(info)
OSError: [Errno 22] Invalid argument

During handling of the above exception, another exception occurred:

Traceback (most recent call last):
  File "C:\Users\86135\AppData\Local\Programs\Python\Python311\Lib\site-packages\apscheduler\executors\base.py", line 125, in run_job
    retval = job.func(*job.args, **job.kwargs)
             ^^^^^^^^^^^^^^^^^^^^^^^^^^^^^^^^^
  File "C:\Users\86135\Desktop\EasyPost\backend\api\dao\https.py", line 404, in run_test_suite
    raise Exception(f"调试测试计划失败: {e}")
Exception: 调试测试计划失败: [Errno 22] Invalid argument
[2024-01-23 10:41:00,079][ThreadPoolExecutor-1_0:16664][task_id:apscheduler.executors.default][base.py:131][ERROR][Job "HttpDao.run_test_suite (trigger: cron[month='*', day='*', day_of_week='*', hour='*', minute='*'], next run at: 2024-01-23 10:42:00 CST)" raised an exception]
Traceback (most recent call last):
  File "C:\Users\86135\Desktop\EasyPost\backend\api\dao\https.py", line 401, in run_test_suite
    result = run_test(case_data)
             ^^^^^^^^^^^^^^^^^^^
  File "C:\Users\86135\Desktop\EasyPost\backend\core\engine\session_runner.py", line 44, in run_test
    suite = GenerateCase().data_to_suite(case_data)
            ^^^^^^^^^^^^^^^^^^^^^^^^^^^^^^^^^^^^^^^
  File "C:\Users\86135\Desktop\EasyPost\backend\core\engine\generate.py", line 28, in data_to_suite
    self.add_test(item, load, suite)
  File "C:\Users\86135\Desktop\EasyPost\backend\core\engine\generate.py", line 36, in add_test
    cls = self.create_test_class(item)
          ^^^^^^^^^^^^^^^^^^^^^^^^^^^^
  File "C:\Users\86135\Desktop\EasyPost\backend\core\engine\generate.py", line 50, in create_test_class
    self.create_case_content(cls, collections)
  File "C:\Users\86135\Desktop\EasyPost\backend\core\engine\generate.py", line 97, in create_case_content
    self.controller.loop(loop_count, cls, test_name, new_test_func)
  File "C:\Users\86135\Desktop\EasyPost\backend\core\engine\base.py", line 61, in loop
    self.info_log('用例第{}次循环\n'.format(c + 1))
  File "C:\Users\86135\Desktop\EasyPost\backend\core\engine\log.py", line 38, in info_log
    self.save_log(message, 'INFO')
  File "C:\Users\86135\Desktop\EasyPost\backend\core\engine\log.py", line 13, in save_log
    print(info)
OSError: [Errno 22] Invalid argument

During handling of the above exception, another exception occurred:

Traceback (most recent call last):
  File "C:\Users\86135\AppData\Local\Programs\Python\Python311\Lib\site-packages\apscheduler\executors\base.py", line 125, in run_job
    retval = job.func(*job.args, **job.kwargs)
             ^^^^^^^^^^^^^^^^^^^^^^^^^^^^^^^^^
  File "C:\Users\86135\Desktop\EasyPost\backend\api\dao\https.py", line 404, in run_test_suite
    raise Exception(f"调试测试计划失败: {e}")
Exception: 调试测试计划失败: [Errno 22] Invalid argument
[2024-01-23 10:42:00,053][ThreadPoolExecutor-1_0:16664][task_id:apscheduler.executors.default][base.py:131][ERROR][Job "HttpDao.run_test_suite (trigger: cron[month='*', day='*', day_of_week='*', hour='*', minute='*'], next run at: 2024-01-23 10:43:00 CST)" raised an exception]
Traceback (most recent call last):
  File "C:\Users\86135\Desktop\EasyPost\backend\api\dao\https.py", line 401, in run_test_suite
    result = run_test(case_data)
             ^^^^^^^^^^^^^^^^^^^
  File "C:\Users\86135\Desktop\EasyPost\backend\core\engine\session_runner.py", line 44, in run_test
    suite = GenerateCase().data_to_suite(case_data)
            ^^^^^^^^^^^^^^^^^^^^^^^^^^^^^^^^^^^^^^^
  File "C:\Users\86135\Desktop\EasyPost\backend\core\engine\generate.py", line 28, in data_to_suite
    self.add_test(item, load, suite)
  File "C:\Users\86135\Desktop\EasyPost\backend\core\engine\generate.py", line 36, in add_test
    cls = self.create_test_class(item)
          ^^^^^^^^^^^^^^^^^^^^^^^^^^^^
  File "C:\Users\86135\Desktop\EasyPost\backend\core\engine\generate.py", line 50, in create_test_class
    self.create_case_content(cls, collections)
  File "C:\Users\86135\Desktop\EasyPost\backend\core\engine\generate.py", line 97, in create_case_content
    self.controller.loop(loop_count, cls, test_name, new_test_func)
  File "C:\Users\86135\Desktop\EasyPost\backend\core\engine\base.py", line 61, in loop
    self.info_log('用例第{}次循环\n'.format(c + 1))
  File "C:\Users\86135\Desktop\EasyPost\backend\core\engine\log.py", line 38, in info_log
    self.save_log(message, 'INFO')
  File "C:\Users\86135\Desktop\EasyPost\backend\core\engine\log.py", line 13, in save_log
    print(info)
OSError: [Errno 22] Invalid argument

During handling of the above exception, another exception occurred:

Traceback (most recent call last):
  File "C:\Users\86135\AppData\Local\Programs\Python\Python311\Lib\site-packages\apscheduler\executors\base.py", line 125, in run_job
    retval = job.func(*job.args, **job.kwargs)
             ^^^^^^^^^^^^^^^^^^^^^^^^^^^^^^^^^
  File "C:\Users\86135\Desktop\EasyPost\backend\api\dao\https.py", line 404, in run_test_suite
    raise Exception(f"调试测试计划失败: {e}")
Exception: 调试测试计划失败: [Errno 22] Invalid argument
[2024-01-23 10:43:00,051][ThreadPoolExecutor-1_0:16664][task_id:apscheduler.executors.default][base.py:131][ERROR][Job "HttpDao.run_test_suite (trigger: cron[month='*', day='*', day_of_week='*', hour='*', minute='*'], next run at: 2024-01-23 10:44:00 CST)" raised an exception]
Traceback (most recent call last):
  File "C:\Users\86135\Desktop\EasyPost\backend\api\dao\https.py", line 401, in run_test_suite
    result = run_test(case_data)
             ^^^^^^^^^^^^^^^^^^^
  File "C:\Users\86135\Desktop\EasyPost\backend\core\engine\session_runner.py", line 44, in run_test
    suite = GenerateCase().data_to_suite(case_data)
            ^^^^^^^^^^^^^^^^^^^^^^^^^^^^^^^^^^^^^^^
  File "C:\Users\86135\Desktop\EasyPost\backend\core\engine\generate.py", line 28, in data_to_suite
    self.add_test(item, load, suite)
  File "C:\Users\86135\Desktop\EasyPost\backend\core\engine\generate.py", line 36, in add_test
    cls = self.create_test_class(item)
          ^^^^^^^^^^^^^^^^^^^^^^^^^^^^
  File "C:\Users\86135\Desktop\EasyPost\backend\core\engine\generate.py", line 50, in create_test_class
    self.create_case_content(cls, collections)
  File "C:\Users\86135\Desktop\EasyPost\backend\core\engine\generate.py", line 97, in create_case_content
    self.controller.loop(loop_count, cls, test_name, new_test_func)
  File "C:\Users\86135\Desktop\EasyPost\backend\core\engine\base.py", line 61, in loop
    self.info_log('用例第{}次循环\n'.format(c + 1))
  File "C:\Users\86135\Desktop\EasyPost\backend\core\engine\log.py", line 38, in info_log
    self.save_log(message, 'INFO')
  File "C:\Users\86135\Desktop\EasyPost\backend\core\engine\log.py", line 13, in save_log
    print(info)
OSError: [Errno 22] Invalid argument

During handling of the above exception, another exception occurred:

Traceback (most recent call last):
  File "C:\Users\86135\AppData\Local\Programs\Python\Python311\Lib\site-packages\apscheduler\executors\base.py", line 125, in run_job
    retval = job.func(*job.args, **job.kwargs)
             ^^^^^^^^^^^^^^^^^^^^^^^^^^^^^^^^^
  File "C:\Users\86135\Desktop\EasyPost\backend\api\dao\https.py", line 404, in run_test_suite
    raise Exception(f"调试测试计划失败: {e}")
Exception: 调试测试计划失败: [Errno 22] Invalid argument
[2024-01-23 10:44:00,050][ThreadPoolExecutor-1_0:16664][task_id:apscheduler.executors.default][base.py:131][ERROR][Job "HttpDao.run_test_suite (trigger: cron[month='*', day='*', day_of_week='*', hour='*', minute='*'], next run at: 2024-01-23 10:45:00 CST)" raised an exception]
Traceback (most recent call last):
  File "C:\Users\86135\Desktop\EasyPost\backend\api\dao\https.py", line 401, in run_test_suite
    result = run_test(case_data)
             ^^^^^^^^^^^^^^^^^^^
  File "C:\Users\86135\Desktop\EasyPost\backend\core\engine\session_runner.py", line 44, in run_test
    suite = GenerateCase().data_to_suite(case_data)
            ^^^^^^^^^^^^^^^^^^^^^^^^^^^^^^^^^^^^^^^
  File "C:\Users\86135\Desktop\EasyPost\backend\core\engine\generate.py", line 28, in data_to_suite
    self.add_test(item, load, suite)
  File "C:\Users\86135\Desktop\EasyPost\backend\core\engine\generate.py", line 36, in add_test
    cls = self.create_test_class(item)
          ^^^^^^^^^^^^^^^^^^^^^^^^^^^^
  File "C:\Users\86135\Desktop\EasyPost\backend\core\engine\generate.py", line 50, in create_test_class
    self.create_case_content(cls, collections)
  File "C:\Users\86135\Desktop\EasyPost\backend\core\engine\generate.py", line 97, in create_case_content
    self.controller.loop(loop_count, cls, test_name, new_test_func)
  File "C:\Users\86135\Desktop\EasyPost\backend\core\engine\base.py", line 61, in loop
    self.info_log('用例第{}次循环\n'.format(c + 1))
  File "C:\Users\86135\Desktop\EasyPost\backend\core\engine\log.py", line 38, in info_log
    self.save_log(message, 'INFO')
  File "C:\Users\86135\Desktop\EasyPost\backend\core\engine\log.py", line 13, in save_log
    print(info)
OSError: [Errno 22] Invalid argument

During handling of the above exception, another exception occurred:

Traceback (most recent call last):
  File "C:\Users\86135\AppData\Local\Programs\Python\Python311\Lib\site-packages\apscheduler\executors\base.py", line 125, in run_job
    retval = job.func(*job.args, **job.kwargs)
             ^^^^^^^^^^^^^^^^^^^^^^^^^^^^^^^^^
  File "C:\Users\86135\Desktop\EasyPost\backend\api\dao\https.py", line 404, in run_test_suite
    raise Exception(f"调试测试计划失败: {e}")
Exception: 调试测试计划失败: [Errno 22] Invalid argument
[2024-01-23 10:45:00,050][ThreadPoolExecutor-1_0:16664][task_id:apscheduler.executors.default][base.py:131][ERROR][Job "HttpDao.run_test_suite (trigger: cron[month='*', day='*', day_of_week='*', hour='*', minute='*'], next run at: 2024-01-23 10:46:00 CST)" raised an exception]
Traceback (most recent call last):
  File "C:\Users\86135\Desktop\EasyPost\backend\api\dao\https.py", line 401, in run_test_suite
    result = run_test(case_data)
             ^^^^^^^^^^^^^^^^^^^
  File "C:\Users\86135\Desktop\EasyPost\backend\core\engine\session_runner.py", line 44, in run_test
    suite = GenerateCase().data_to_suite(case_data)
            ^^^^^^^^^^^^^^^^^^^^^^^^^^^^^^^^^^^^^^^
  File "C:\Users\86135\Desktop\EasyPost\backend\core\engine\generate.py", line 28, in data_to_suite
    self.add_test(item, load, suite)
  File "C:\Users\86135\Desktop\EasyPost\backend\core\engine\generate.py", line 36, in add_test
    cls = self.create_test_class(item)
          ^^^^^^^^^^^^^^^^^^^^^^^^^^^^
  File "C:\Users\86135\Desktop\EasyPost\backend\core\engine\generate.py", line 50, in create_test_class
    self.create_case_content(cls, collections)
  File "C:\Users\86135\Desktop\EasyPost\backend\core\engine\generate.py", line 97, in create_case_content
    self.controller.loop(loop_count, cls, test_name, new_test_func)
  File "C:\Users\86135\Desktop\EasyPost\backend\core\engine\base.py", line 61, in loop
    self.info_log('用例第{}次循环\n'.format(c + 1))
  File "C:\Users\86135\Desktop\EasyPost\backend\core\engine\log.py", line 38, in info_log
    self.save_log(message, 'INFO')
  File "C:\Users\86135\Desktop\EasyPost\backend\core\engine\log.py", line 13, in save_log
    print(info)
OSError: [Errno 22] Invalid argument

During handling of the above exception, another exception occurred:

Traceback (most recent call last):
  File "C:\Users\86135\AppData\Local\Programs\Python\Python311\Lib\site-packages\apscheduler\executors\base.py", line 125, in run_job
    retval = job.func(*job.args, **job.kwargs)
             ^^^^^^^^^^^^^^^^^^^^^^^^^^^^^^^^^
  File "C:\Users\86135\Desktop\EasyPost\backend\api\dao\https.py", line 404, in run_test_suite
    raise Exception(f"调试测试计划失败: {e}")
Exception: 调试测试计划失败: [Errno 22] Invalid argument
[2024-01-23 10:46:00,050][ThreadPoolExecutor-1_0:16664][task_id:apscheduler.executors.default][base.py:131][ERROR][Job "HttpDao.run_test_suite (trigger: cron[month='*', day='*', day_of_week='*', hour='*', minute='*'], next run at: 2024-01-23 10:47:00 CST)" raised an exception]
Traceback (most recent call last):
  File "C:\Users\86135\Desktop\EasyPost\backend\api\dao\https.py", line 401, in run_test_suite
    result = run_test(case_data)
             ^^^^^^^^^^^^^^^^^^^
  File "C:\Users\86135\Desktop\EasyPost\backend\core\engine\session_runner.py", line 44, in run_test
    suite = GenerateCase().data_to_suite(case_data)
            ^^^^^^^^^^^^^^^^^^^^^^^^^^^^^^^^^^^^^^^
  File "C:\Users\86135\Desktop\EasyPost\backend\core\engine\generate.py", line 28, in data_to_suite
    self.add_test(item, load, suite)
  File "C:\Users\86135\Desktop\EasyPost\backend\core\engine\generate.py", line 36, in add_test
    cls = self.create_test_class(item)
          ^^^^^^^^^^^^^^^^^^^^^^^^^^^^
  File "C:\Users\86135\Desktop\EasyPost\backend\core\engine\generate.py", line 50, in create_test_class
    self.create_case_content(cls, collections)
  File "C:\Users\86135\Desktop\EasyPost\backend\core\engine\generate.py", line 97, in create_case_content
    self.controller.loop(loop_count, cls, test_name, new_test_func)
  File "C:\Users\86135\Desktop\EasyPost\backend\core\engine\base.py", line 61, in loop
    self.info_log('用例第{}次循环\n'.format(c + 1))
  File "C:\Users\86135\Desktop\EasyPost\backend\core\engine\log.py", line 38, in info_log
    self.save_log(message, 'INFO')
  File "C:\Users\86135\Desktop\EasyPost\backend\core\engine\log.py", line 13, in save_log
    print(info)
OSError: [Errno 22] Invalid argument

During handling of the above exception, another exception occurred:

Traceback (most recent call last):
  File "C:\Users\86135\AppData\Local\Programs\Python\Python311\Lib\site-packages\apscheduler\executors\base.py", line 125, in run_job
    retval = job.func(*job.args, **job.kwargs)
             ^^^^^^^^^^^^^^^^^^^^^^^^^^^^^^^^^
  File "C:\Users\86135\Desktop\EasyPost\backend\api\dao\https.py", line 404, in run_test_suite
    raise Exception(f"调试测试计划失败: {e}")
Exception: 调试测试计划失败: [Errno 22] Invalid argument
[2024-01-23 10:47:00,069][ThreadPoolExecutor-1_0:16664][task_id:apscheduler.executors.default][base.py:131][ERROR][Job "HttpDao.run_test_suite (trigger: cron[month='*', day='*', day_of_week='*', hour='*', minute='*'], next run at: 2024-01-23 10:48:00 CST)" raised an exception]
Traceback (most recent call last):
  File "C:\Users\86135\Desktop\EasyPost\backend\api\dao\https.py", line 401, in run_test_suite
    result = run_test(case_data)
             ^^^^^^^^^^^^^^^^^^^
  File "C:\Users\86135\Desktop\EasyPost\backend\core\engine\session_runner.py", line 44, in run_test
    suite = GenerateCase().data_to_suite(case_data)
            ^^^^^^^^^^^^^^^^^^^^^^^^^^^^^^^^^^^^^^^
  File "C:\Users\86135\Desktop\EasyPost\backend\core\engine\generate.py", line 28, in data_to_suite
    self.add_test(item, load, suite)
  File "C:\Users\86135\Desktop\EasyPost\backend\core\engine\generate.py", line 36, in add_test
    cls = self.create_test_class(item)
          ^^^^^^^^^^^^^^^^^^^^^^^^^^^^
  File "C:\Users\86135\Desktop\EasyPost\backend\core\engine\generate.py", line 50, in create_test_class
    self.create_case_content(cls, collections)
  File "C:\Users\86135\Desktop\EasyPost\backend\core\engine\generate.py", line 97, in create_case_content
    self.controller.loop(loop_count, cls, test_name, new_test_func)
  File "C:\Users\86135\Desktop\EasyPost\backend\core\engine\base.py", line 61, in loop
    self.info_log('用例第{}次循环\n'.format(c + 1))
  File "C:\Users\86135\Desktop\EasyPost\backend\core\engine\log.py", line 38, in info_log
    self.save_log(message, 'INFO')
  File "C:\Users\86135\Desktop\EasyPost\backend\core\engine\log.py", line 13, in save_log
    print(info)
OSError: [Errno 22] Invalid argument

During handling of the above exception, another exception occurred:

Traceback (most recent call last):
  File "C:\Users\86135\AppData\Local\Programs\Python\Python311\Lib\site-packages\apscheduler\executors\base.py", line 125, in run_job
    retval = job.func(*job.args, **job.kwargs)
             ^^^^^^^^^^^^^^^^^^^^^^^^^^^^^^^^^
  File "C:\Users\86135\Desktop\EasyPost\backend\api\dao\https.py", line 404, in run_test_suite
    raise Exception(f"调试测试计划失败: {e}")
Exception: 调试测试计划失败: [Errno 22] Invalid argument
[2024-01-23 10:48:00,047][ThreadPoolExecutor-1_0:16664][task_id:apscheduler.executors.default][base.py:131][ERROR][Job "HttpDao.run_test_suite (trigger: cron[month='*', day='*', day_of_week='*', hour='*', minute='*'], next run at: 2024-01-23 10:49:00 CST)" raised an exception]
Traceback (most recent call last):
  File "C:\Users\86135\Desktop\EasyPost\backend\api\dao\https.py", line 401, in run_test_suite
    result = run_test(case_data)
             ^^^^^^^^^^^^^^^^^^^
  File "C:\Users\86135\Desktop\EasyPost\backend\core\engine\session_runner.py", line 44, in run_test
    suite = GenerateCase().data_to_suite(case_data)
            ^^^^^^^^^^^^^^^^^^^^^^^^^^^^^^^^^^^^^^^
  File "C:\Users\86135\Desktop\EasyPost\backend\core\engine\generate.py", line 28, in data_to_suite
    self.add_test(item, load, suite)
  File "C:\Users\86135\Desktop\EasyPost\backend\core\engine\generate.py", line 36, in add_test
    cls = self.create_test_class(item)
          ^^^^^^^^^^^^^^^^^^^^^^^^^^^^
  File "C:\Users\86135\Desktop\EasyPost\backend\core\engine\generate.py", line 50, in create_test_class
    self.create_case_content(cls, collections)
  File "C:\Users\86135\Desktop\EasyPost\backend\core\engine\generate.py", line 97, in create_case_content
    self.controller.loop(loop_count, cls, test_name, new_test_func)
  File "C:\Users\86135\Desktop\EasyPost\backend\core\engine\base.py", line 61, in loop
    self.info_log('用例第{}次循环\n'.format(c + 1))
  File "C:\Users\86135\Desktop\EasyPost\backend\core\engine\log.py", line 38, in info_log
    self.save_log(message, 'INFO')
  File "C:\Users\86135\Desktop\EasyPost\backend\core\engine\log.py", line 13, in save_log
    print(info)
OSError: [Errno 22] Invalid argument

During handling of the above exception, another exception occurred:

Traceback (most recent call last):
  File "C:\Users\86135\AppData\Local\Programs\Python\Python311\Lib\site-packages\apscheduler\executors\base.py", line 125, in run_job
    retval = job.func(*job.args, **job.kwargs)
             ^^^^^^^^^^^^^^^^^^^^^^^^^^^^^^^^^
  File "C:\Users\86135\Desktop\EasyPost\backend\api\dao\https.py", line 404, in run_test_suite
    raise Exception(f"调试测试计划失败: {e}")
Exception: 调试测试计划失败: [Errno 22] Invalid argument
[2024-01-23 10:49:00,047][ThreadPoolExecutor-1_0:16664][task_id:apscheduler.executors.default][base.py:131][ERROR][Job "HttpDao.run_test_suite (trigger: cron[month='*', day='*', day_of_week='*', hour='*', minute='*'], next run at: 2024-01-23 10:50:00 CST)" raised an exception]
Traceback (most recent call last):
  File "C:\Users\86135\Desktop\EasyPost\backend\api\dao\https.py", line 401, in run_test_suite
    result = run_test(case_data)
             ^^^^^^^^^^^^^^^^^^^
  File "C:\Users\86135\Desktop\EasyPost\backend\core\engine\session_runner.py", line 44, in run_test
    suite = GenerateCase().data_to_suite(case_data)
            ^^^^^^^^^^^^^^^^^^^^^^^^^^^^^^^^^^^^^^^
  File "C:\Users\86135\Desktop\EasyPost\backend\core\engine\generate.py", line 28, in data_to_suite
    self.add_test(item, load, suite)
  File "C:\Users\86135\Desktop\EasyPost\backend\core\engine\generate.py", line 36, in add_test
    cls = self.create_test_class(item)
          ^^^^^^^^^^^^^^^^^^^^^^^^^^^^
  File "C:\Users\86135\Desktop\EasyPost\backend\core\engine\generate.py", line 50, in create_test_class
    self.create_case_content(cls, collections)
  File "C:\Users\86135\Desktop\EasyPost\backend\core\engine\generate.py", line 97, in create_case_content
    self.controller.loop(loop_count, cls, test_name, new_test_func)
  File "C:\Users\86135\Desktop\EasyPost\backend\core\engine\base.py", line 61, in loop
    self.info_log('用例第{}次循环\n'.format(c + 1))
  File "C:\Users\86135\Desktop\EasyPost\backend\core\engine\log.py", line 38, in info_log
    self.save_log(message, 'INFO')
  File "C:\Users\86135\Desktop\EasyPost\backend\core\engine\log.py", line 13, in save_log
    print(info)
OSError: [Errno 22] Invalid argument

During handling of the above exception, another exception occurred:

Traceback (most recent call last):
  File "C:\Users\86135\AppData\Local\Programs\Python\Python311\Lib\site-packages\apscheduler\executors\base.py", line 125, in run_job
    retval = job.func(*job.args, **job.kwargs)
             ^^^^^^^^^^^^^^^^^^^^^^^^^^^^^^^^^
  File "C:\Users\86135\Desktop\EasyPost\backend\api\dao\https.py", line 404, in run_test_suite
    raise Exception(f"调试测试计划失败: {e}")
Exception: 调试测试计划失败: [Errno 22] Invalid argument
[2024-01-23 10:50:00,062][ThreadPoolExecutor-1_0:16664][task_id:apscheduler.executors.default][base.py:131][ERROR][Job "HttpDao.run_test_suite (trigger: cron[month='*', day='*', day_of_week='*', hour='*', minute='*'], next run at: 2024-01-23 10:51:00 CST)" raised an exception]
Traceback (most recent call last):
  File "C:\Users\86135\Desktop\EasyPost\backend\api\dao\https.py", line 401, in run_test_suite
    result = run_test(case_data)
             ^^^^^^^^^^^^^^^^^^^
  File "C:\Users\86135\Desktop\EasyPost\backend\core\engine\session_runner.py", line 44, in run_test
    suite = GenerateCase().data_to_suite(case_data)
            ^^^^^^^^^^^^^^^^^^^^^^^^^^^^^^^^^^^^^^^
  File "C:\Users\86135\Desktop\EasyPost\backend\core\engine\generate.py", line 28, in data_to_suite
    self.add_test(item, load, suite)
  File "C:\Users\86135\Desktop\EasyPost\backend\core\engine\generate.py", line 36, in add_test
    cls = self.create_test_class(item)
          ^^^^^^^^^^^^^^^^^^^^^^^^^^^^
  File "C:\Users\86135\Desktop\EasyPost\backend\core\engine\generate.py", line 50, in create_test_class
    self.create_case_content(cls, collections)
  File "C:\Users\86135\Desktop\EasyPost\backend\core\engine\generate.py", line 97, in create_case_content
    self.controller.loop(loop_count, cls, test_name, new_test_func)
  File "C:\Users\86135\Desktop\EasyPost\backend\core\engine\base.py", line 61, in loop
    self.info_log('用例第{}次循环\n'.format(c + 1))
  File "C:\Users\86135\Desktop\EasyPost\backend\core\engine\log.py", line 38, in info_log
    self.save_log(message, 'INFO')
  File "C:\Users\86135\Desktop\EasyPost\backend\core\engine\log.py", line 13, in save_log
    print(info)
OSError: [Errno 22] Invalid argument

During handling of the above exception, another exception occurred:

Traceback (most recent call last):
  File "C:\Users\86135\AppData\Local\Programs\Python\Python311\Lib\site-packages\apscheduler\executors\base.py", line 125, in run_job
    retval = job.func(*job.args, **job.kwargs)
             ^^^^^^^^^^^^^^^^^^^^^^^^^^^^^^^^^
  File "C:\Users\86135\Desktop\EasyPost\backend\api\dao\https.py", line 404, in run_test_suite
    raise Exception(f"调试测试计划失败: {e}")
Exception: 调试测试计划失败: [Errno 22] Invalid argument
[2024-01-23 10:51:00,054][ThreadPoolExecutor-1_0:16664][task_id:apscheduler.executors.default][base.py:131][ERROR][Job "HttpDao.run_test_suite (trigger: cron[month='*', day='*', day_of_week='*', hour='*', minute='*'], next run at: 2024-01-23 10:52:00 CST)" raised an exception]
Traceback (most recent call last):
  File "C:\Users\86135\Desktop\EasyPost\backend\api\dao\https.py", line 401, in run_test_suite
    result = run_test(case_data)
             ^^^^^^^^^^^^^^^^^^^
  File "C:\Users\86135\Desktop\EasyPost\backend\core\engine\session_runner.py", line 44, in run_test
    suite = GenerateCase().data_to_suite(case_data)
            ^^^^^^^^^^^^^^^^^^^^^^^^^^^^^^^^^^^^^^^
  File "C:\Users\86135\Desktop\EasyPost\backend\core\engine\generate.py", line 28, in data_to_suite
    self.add_test(item, load, suite)
  File "C:\Users\86135\Desktop\EasyPost\backend\core\engine\generate.py", line 36, in add_test
    cls = self.create_test_class(item)
          ^^^^^^^^^^^^^^^^^^^^^^^^^^^^
  File "C:\Users\86135\Desktop\EasyPost\backend\core\engine\generate.py", line 50, in create_test_class
    self.create_case_content(cls, collections)
  File "C:\Users\86135\Desktop\EasyPost\backend\core\engine\generate.py", line 97, in create_case_content
    self.controller.loop(loop_count, cls, test_name, new_test_func)
  File "C:\Users\86135\Desktop\EasyPost\backend\core\engine\base.py", line 61, in loop
    self.info_log('用例第{}次循环\n'.format(c + 1))
  File "C:\Users\86135\Desktop\EasyPost\backend\core\engine\log.py", line 38, in info_log
    self.save_log(message, 'INFO')
  File "C:\Users\86135\Desktop\EasyPost\backend\core\engine\log.py", line 13, in save_log
    print(info)
OSError: [Errno 22] Invalid argument

During handling of the above exception, another exception occurred:

Traceback (most recent call last):
  File "C:\Users\86135\AppData\Local\Programs\Python\Python311\Lib\site-packages\apscheduler\executors\base.py", line 125, in run_job
    retval = job.func(*job.args, **job.kwargs)
             ^^^^^^^^^^^^^^^^^^^^^^^^^^^^^^^^^
  File "C:\Users\86135\Desktop\EasyPost\backend\api\dao\https.py", line 404, in run_test_suite
    raise Exception(f"调试测试计划失败: {e}")
Exception: 调试测试计划失败: [Errno 22] Invalid argument
[2024-01-23 10:52:00,041][ThreadPoolExecutor-1_0:16664][task_id:apscheduler.executors.default][base.py:131][ERROR][Job "HttpDao.run_test_suite (trigger: cron[month='*', day='*', day_of_week='*', hour='*', minute='*'], next run at: 2024-01-23 10:53:00 CST)" raised an exception]
Traceback (most recent call last):
  File "C:\Users\86135\Desktop\EasyPost\backend\api\dao\https.py", line 401, in run_test_suite
    result = run_test(case_data)
             ^^^^^^^^^^^^^^^^^^^
  File "C:\Users\86135\Desktop\EasyPost\backend\core\engine\session_runner.py", line 44, in run_test
    suite = GenerateCase().data_to_suite(case_data)
            ^^^^^^^^^^^^^^^^^^^^^^^^^^^^^^^^^^^^^^^
  File "C:\Users\86135\Desktop\EasyPost\backend\core\engine\generate.py", line 28, in data_to_suite
    self.add_test(item, load, suite)
  File "C:\Users\86135\Desktop\EasyPost\backend\core\engine\generate.py", line 36, in add_test
    cls = self.create_test_class(item)
          ^^^^^^^^^^^^^^^^^^^^^^^^^^^^
  File "C:\Users\86135\Desktop\EasyPost\backend\core\engine\generate.py", line 50, in create_test_class
    self.create_case_content(cls, collections)
  File "C:\Users\86135\Desktop\EasyPost\backend\core\engine\generate.py", line 97, in create_case_content
    self.controller.loop(loop_count, cls, test_name, new_test_func)
  File "C:\Users\86135\Desktop\EasyPost\backend\core\engine\base.py", line 61, in loop
    self.info_log('用例第{}次循环\n'.format(c + 1))
  File "C:\Users\86135\Desktop\EasyPost\backend\core\engine\log.py", line 38, in info_log
    self.save_log(message, 'INFO')
  File "C:\Users\86135\Desktop\EasyPost\backend\core\engine\log.py", line 13, in save_log
    print(info)
OSError: [Errno 22] Invalid argument

During handling of the above exception, another exception occurred:

Traceback (most recent call last):
  File "C:\Users\86135\AppData\Local\Programs\Python\Python311\Lib\site-packages\apscheduler\executors\base.py", line 125, in run_job
    retval = job.func(*job.args, **job.kwargs)
             ^^^^^^^^^^^^^^^^^^^^^^^^^^^^^^^^^
  File "C:\Users\86135\Desktop\EasyPost\backend\api\dao\https.py", line 404, in run_test_suite
    raise Exception(f"调试测试计划失败: {e}")
Exception: 调试测试计划失败: [Errno 22] Invalid argument
[2024-01-23 10:53:00,041][ThreadPoolExecutor-1_0:16664][task_id:apscheduler.executors.default][base.py:131][ERROR][Job "HttpDao.run_test_suite (trigger: cron[month='*', day='*', day_of_week='*', hour='*', minute='*'], next run at: 2024-01-23 10:54:00 CST)" raised an exception]
Traceback (most recent call last):
  File "C:\Users\86135\Desktop\EasyPost\backend\api\dao\https.py", line 401, in run_test_suite
    result = run_test(case_data)
             ^^^^^^^^^^^^^^^^^^^
  File "C:\Users\86135\Desktop\EasyPost\backend\core\engine\session_runner.py", line 44, in run_test
    suite = GenerateCase().data_to_suite(case_data)
            ^^^^^^^^^^^^^^^^^^^^^^^^^^^^^^^^^^^^^^^
  File "C:\Users\86135\Desktop\EasyPost\backend\core\engine\generate.py", line 28, in data_to_suite
    self.add_test(item, load, suite)
  File "C:\Users\86135\Desktop\EasyPost\backend\core\engine\generate.py", line 36, in add_test
    cls = self.create_test_class(item)
          ^^^^^^^^^^^^^^^^^^^^^^^^^^^^
  File "C:\Users\86135\Desktop\EasyPost\backend\core\engine\generate.py", line 50, in create_test_class
    self.create_case_content(cls, collections)
  File "C:\Users\86135\Desktop\EasyPost\backend\core\engine\generate.py", line 97, in create_case_content
    self.controller.loop(loop_count, cls, test_name, new_test_func)
  File "C:\Users\86135\Desktop\EasyPost\backend\core\engine\base.py", line 61, in loop
    self.info_log('用例第{}次循环\n'.format(c + 1))
  File "C:\Users\86135\Desktop\EasyPost\backend\core\engine\log.py", line 38, in info_log
    self.save_log(message, 'INFO')
  File "C:\Users\86135\Desktop\EasyPost\backend\core\engine\log.py", line 13, in save_log
    print(info)
OSError: [Errno 22] Invalid argument

During handling of the above exception, another exception occurred:

Traceback (most recent call last):
  File "C:\Users\86135\AppData\Local\Programs\Python\Python311\Lib\site-packages\apscheduler\executors\base.py", line 125, in run_job
    retval = job.func(*job.args, **job.kwargs)
             ^^^^^^^^^^^^^^^^^^^^^^^^^^^^^^^^^
  File "C:\Users\86135\Desktop\EasyPost\backend\api\dao\https.py", line 404, in run_test_suite
    raise Exception(f"调试测试计划失败: {e}")
Exception: 调试测试计划失败: [Errno 22] Invalid argument
[2024-01-23 10:54:00,060][ThreadPoolExecutor-1_0:16664][task_id:apscheduler.executors.default][base.py:131][ERROR][Job "HttpDao.run_test_suite (trigger: cron[month='*', day='*', day_of_week='*', hour='*', minute='*'], next run at: 2024-01-23 10:55:00 CST)" raised an exception]
Traceback (most recent call last):
  File "C:\Users\86135\Desktop\EasyPost\backend\api\dao\https.py", line 401, in run_test_suite
    result = run_test(case_data)
             ^^^^^^^^^^^^^^^^^^^
  File "C:\Users\86135\Desktop\EasyPost\backend\core\engine\session_runner.py", line 44, in run_test
    suite = GenerateCase().data_to_suite(case_data)
            ^^^^^^^^^^^^^^^^^^^^^^^^^^^^^^^^^^^^^^^
  File "C:\Users\86135\Desktop\EasyPost\backend\core\engine\generate.py", line 28, in data_to_suite
    self.add_test(item, load, suite)
  File "C:\Users\86135\Desktop\EasyPost\backend\core\engine\generate.py", line 36, in add_test
    cls = self.create_test_class(item)
          ^^^^^^^^^^^^^^^^^^^^^^^^^^^^
  File "C:\Users\86135\Desktop\EasyPost\backend\core\engine\generate.py", line 50, in create_test_class
    self.create_case_content(cls, collections)
  File "C:\Users\86135\Desktop\EasyPost\backend\core\engine\generate.py", line 97, in create_case_content
    self.controller.loop(loop_count, cls, test_name, new_test_func)
  File "C:\Users\86135\Desktop\EasyPost\backend\core\engine\base.py", line 61, in loop
    self.info_log('用例第{}次循环\n'.format(c + 1))
  File "C:\Users\86135\Desktop\EasyPost\backend\core\engine\log.py", line 38, in info_log
    self.save_log(message, 'INFO')
  File "C:\Users\86135\Desktop\EasyPost\backend\core\engine\log.py", line 13, in save_log
    print(info)
OSError: [Errno 22] Invalid argument

During handling of the above exception, another exception occurred:

Traceback (most recent call last):
  File "C:\Users\86135\AppData\Local\Programs\Python\Python311\Lib\site-packages\apscheduler\executors\base.py", line 125, in run_job
    retval = job.func(*job.args, **job.kwargs)
             ^^^^^^^^^^^^^^^^^^^^^^^^^^^^^^^^^
  File "C:\Users\86135\Desktop\EasyPost\backend\api\dao\https.py", line 404, in run_test_suite
    raise Exception(f"调试测试计划失败: {e}")
Exception: 调试测试计划失败: [Errno 22] Invalid argument
[2024-01-23 10:55:00,046][ThreadPoolExecutor-1_0:16664][task_id:apscheduler.executors.default][base.py:131][ERROR][Job "HttpDao.run_test_suite (trigger: cron[month='*', day='*', day_of_week='*', hour='*', minute='*'], next run at: 2024-01-23 10:56:00 CST)" raised an exception]
Traceback (most recent call last):
  File "C:\Users\86135\Desktop\EasyPost\backend\api\dao\https.py", line 401, in run_test_suite
    result = run_test(case_data)
             ^^^^^^^^^^^^^^^^^^^
  File "C:\Users\86135\Desktop\EasyPost\backend\core\engine\session_runner.py", line 44, in run_test
    suite = GenerateCase().data_to_suite(case_data)
            ^^^^^^^^^^^^^^^^^^^^^^^^^^^^^^^^^^^^^^^
  File "C:\Users\86135\Desktop\EasyPost\backend\core\engine\generate.py", line 28, in data_to_suite
    self.add_test(item, load, suite)
  File "C:\Users\86135\Desktop\EasyPost\backend\core\engine\generate.py", line 36, in add_test
    cls = self.create_test_class(item)
          ^^^^^^^^^^^^^^^^^^^^^^^^^^^^
  File "C:\Users\86135\Desktop\EasyPost\backend\core\engine\generate.py", line 50, in create_test_class
    self.create_case_content(cls, collections)
  File "C:\Users\86135\Desktop\EasyPost\backend\core\engine\generate.py", line 97, in create_case_content
    self.controller.loop(loop_count, cls, test_name, new_test_func)
  File "C:\Users\86135\Desktop\EasyPost\backend\core\engine\base.py", line 61, in loop
    self.info_log('用例第{}次循环\n'.format(c + 1))
  File "C:\Users\86135\Desktop\EasyPost\backend\core\engine\log.py", line 38, in info_log
    self.save_log(message, 'INFO')
  File "C:\Users\86135\Desktop\EasyPost\backend\core\engine\log.py", line 13, in save_log
    print(info)
OSError: [Errno 22] Invalid argument

During handling of the above exception, another exception occurred:

Traceback (most recent call last):
  File "C:\Users\86135\AppData\Local\Programs\Python\Python311\Lib\site-packages\apscheduler\executors\base.py", line 125, in run_job
    retval = job.func(*job.args, **job.kwargs)
             ^^^^^^^^^^^^^^^^^^^^^^^^^^^^^^^^^
  File "C:\Users\86135\Desktop\EasyPost\backend\api\dao\https.py", line 404, in run_test_suite
    raise Exception(f"调试测试计划失败: {e}")
Exception: 调试测试计划失败: [Errno 22] Invalid argument
[2024-01-23 10:56:00,046][ThreadPoolExecutor-1_0:16664][task_id:apscheduler.executors.default][base.py:131][ERROR][Job "HttpDao.run_test_suite (trigger: cron[month='*', day='*', day_of_week='*', hour='*', minute='*'], next run at: 2024-01-23 10:57:00 CST)" raised an exception]
Traceback (most recent call last):
  File "C:\Users\86135\Desktop\EasyPost\backend\api\dao\https.py", line 401, in run_test_suite
    result = run_test(case_data)
             ^^^^^^^^^^^^^^^^^^^
  File "C:\Users\86135\Desktop\EasyPost\backend\core\engine\session_runner.py", line 44, in run_test
    suite = GenerateCase().data_to_suite(case_data)
            ^^^^^^^^^^^^^^^^^^^^^^^^^^^^^^^^^^^^^^^
  File "C:\Users\86135\Desktop\EasyPost\backend\core\engine\generate.py", line 28, in data_to_suite
    self.add_test(item, load, suite)
  File "C:\Users\86135\Desktop\EasyPost\backend\core\engine\generate.py", line 36, in add_test
    cls = self.create_test_class(item)
          ^^^^^^^^^^^^^^^^^^^^^^^^^^^^
  File "C:\Users\86135\Desktop\EasyPost\backend\core\engine\generate.py", line 50, in create_test_class
    self.create_case_content(cls, collections)
  File "C:\Users\86135\Desktop\EasyPost\backend\core\engine\generate.py", line 97, in create_case_content
    self.controller.loop(loop_count, cls, test_name, new_test_func)
  File "C:\Users\86135\Desktop\EasyPost\backend\core\engine\base.py", line 61, in loop
    self.info_log('用例第{}次循环\n'.format(c + 1))
  File "C:\Users\86135\Desktop\EasyPost\backend\core\engine\log.py", line 38, in info_log
    self.save_log(message, 'INFO')
  File "C:\Users\86135\Desktop\EasyPost\backend\core\engine\log.py", line 13, in save_log
    print(info)
OSError: [Errno 22] Invalid argument

During handling of the above exception, another exception occurred:

Traceback (most recent call last):
  File "C:\Users\86135\AppData\Local\Programs\Python\Python311\Lib\site-packages\apscheduler\executors\base.py", line 125, in run_job
    retval = job.func(*job.args, **job.kwargs)
             ^^^^^^^^^^^^^^^^^^^^^^^^^^^^^^^^^
  File "C:\Users\86135\Desktop\EasyPost\backend\api\dao\https.py", line 404, in run_test_suite
    raise Exception(f"调试测试计划失败: {e}")
Exception: 调试测试计划失败: [Errno 22] Invalid argument
[2024-01-23 10:57:00,052][ThreadPoolExecutor-1_0:16664][task_id:apscheduler.executors.default][base.py:131][ERROR][Job "HttpDao.run_test_suite (trigger: cron[month='*', day='*', day_of_week='*', hour='*', minute='*'], next run at: 2024-01-23 10:58:00 CST)" raised an exception]
Traceback (most recent call last):
  File "C:\Users\86135\Desktop\EasyPost\backend\api\dao\https.py", line 401, in run_test_suite
    result = run_test(case_data)
             ^^^^^^^^^^^^^^^^^^^
  File "C:\Users\86135\Desktop\EasyPost\backend\core\engine\session_runner.py", line 44, in run_test
    suite = GenerateCase().data_to_suite(case_data)
            ^^^^^^^^^^^^^^^^^^^^^^^^^^^^^^^^^^^^^^^
  File "C:\Users\86135\Desktop\EasyPost\backend\core\engine\generate.py", line 28, in data_to_suite
    self.add_test(item, load, suite)
  File "C:\Users\86135\Desktop\EasyPost\backend\core\engine\generate.py", line 36, in add_test
    cls = self.create_test_class(item)
          ^^^^^^^^^^^^^^^^^^^^^^^^^^^^
  File "C:\Users\86135\Desktop\EasyPost\backend\core\engine\generate.py", line 50, in create_test_class
    self.create_case_content(cls, collections)
  File "C:\Users\86135\Desktop\EasyPost\backend\core\engine\generate.py", line 97, in create_case_content
    self.controller.loop(loop_count, cls, test_name, new_test_func)
  File "C:\Users\86135\Desktop\EasyPost\backend\core\engine\base.py", line 61, in loop
    self.info_log('用例第{}次循环\n'.format(c + 1))
  File "C:\Users\86135\Desktop\EasyPost\backend\core\engine\log.py", line 38, in info_log
    self.save_log(message, 'INFO')
  File "C:\Users\86135\Desktop\EasyPost\backend\core\engine\log.py", line 13, in save_log
    print(info)
OSError: [Errno 22] Invalid argument

During handling of the above exception, another exception occurred:

Traceback (most recent call last):
  File "C:\Users\86135\AppData\Local\Programs\Python\Python311\Lib\site-packages\apscheduler\executors\base.py", line 125, in run_job
    retval = job.func(*job.args, **job.kwargs)
             ^^^^^^^^^^^^^^^^^^^^^^^^^^^^^^^^^
  File "C:\Users\86135\Desktop\EasyPost\backend\api\dao\https.py", line 404, in run_test_suite
    raise Exception(f"调试测试计划失败: {e}")
Exception: 调试测试计划失败: [Errno 22] Invalid argument
[2024-01-23 10:58:00,048][ThreadPoolExecutor-1_0:16664][task_id:apscheduler.executors.default][base.py:131][ERROR][Job "HttpDao.run_test_suite (trigger: cron[month='*', day='*', day_of_week='*', hour='*', minute='*'], next run at: 2024-01-23 10:59:00 CST)" raised an exception]
Traceback (most recent call last):
  File "C:\Users\86135\Desktop\EasyPost\backend\api\dao\https.py", line 401, in run_test_suite
    result = run_test(case_data)
             ^^^^^^^^^^^^^^^^^^^
  File "C:\Users\86135\Desktop\EasyPost\backend\core\engine\session_runner.py", line 44, in run_test
    suite = GenerateCase().data_to_suite(case_data)
            ^^^^^^^^^^^^^^^^^^^^^^^^^^^^^^^^^^^^^^^
  File "C:\Users\86135\Desktop\EasyPost\backend\core\engine\generate.py", line 28, in data_to_suite
    self.add_test(item, load, suite)
  File "C:\Users\86135\Desktop\EasyPost\backend\core\engine\generate.py", line 36, in add_test
    cls = self.create_test_class(item)
          ^^^^^^^^^^^^^^^^^^^^^^^^^^^^
  File "C:\Users\86135\Desktop\EasyPost\backend\core\engine\generate.py", line 50, in create_test_class
    self.create_case_content(cls, collections)
  File "C:\Users\86135\Desktop\EasyPost\backend\core\engine\generate.py", line 97, in create_case_content
    self.controller.loop(loop_count, cls, test_name, new_test_func)
  File "C:\Users\86135\Desktop\EasyPost\backend\core\engine\base.py", line 61, in loop
    self.info_log('用例第{}次循环\n'.format(c + 1))
  File "C:\Users\86135\Desktop\EasyPost\backend\core\engine\log.py", line 38, in info_log
    self.save_log(message, 'INFO')
  File "C:\Users\86135\Desktop\EasyPost\backend\core\engine\log.py", line 13, in save_log
    print(info)
OSError: [Errno 22] Invalid argument

During handling of the above exception, another exception occurred:

Traceback (most recent call last):
  File "C:\Users\86135\AppData\Local\Programs\Python\Python311\Lib\site-packages\apscheduler\executors\base.py", line 125, in run_job
    retval = job.func(*job.args, **job.kwargs)
             ^^^^^^^^^^^^^^^^^^^^^^^^^^^^^^^^^
  File "C:\Users\86135\Desktop\EasyPost\backend\api\dao\https.py", line 404, in run_test_suite
    raise Exception(f"调试测试计划失败: {e}")
Exception: 调试测试计划失败: [Errno 22] Invalid argument
[2024-01-23 10:59:00,050][ThreadPoolExecutor-1_0:16664][task_id:apscheduler.executors.default][base.py:131][ERROR][Job "HttpDao.run_test_suite (trigger: cron[month='*', day='*', day_of_week='*', hour='*', minute='*'], next run at: 2024-01-23 11:00:00 CST)" raised an exception]
Traceback (most recent call last):
  File "C:\Users\86135\Desktop\EasyPost\backend\api\dao\https.py", line 401, in run_test_suite
    result = run_test(case_data)
             ^^^^^^^^^^^^^^^^^^^
  File "C:\Users\86135\Desktop\EasyPost\backend\core\engine\session_runner.py", line 44, in run_test
    suite = GenerateCase().data_to_suite(case_data)
            ^^^^^^^^^^^^^^^^^^^^^^^^^^^^^^^^^^^^^^^
  File "C:\Users\86135\Desktop\EasyPost\backend\core\engine\generate.py", line 28, in data_to_suite
    self.add_test(item, load, suite)
  File "C:\Users\86135\Desktop\EasyPost\backend\core\engine\generate.py", line 36, in add_test
    cls = self.create_test_class(item)
          ^^^^^^^^^^^^^^^^^^^^^^^^^^^^
  File "C:\Users\86135\Desktop\EasyPost\backend\core\engine\generate.py", line 50, in create_test_class
    self.create_case_content(cls, collections)
  File "C:\Users\86135\Desktop\EasyPost\backend\core\engine\generate.py", line 97, in create_case_content
    self.controller.loop(loop_count, cls, test_name, new_test_func)
  File "C:\Users\86135\Desktop\EasyPost\backend\core\engine\base.py", line 61, in loop
    self.info_log('用例第{}次循环\n'.format(c + 1))
  File "C:\Users\86135\Desktop\EasyPost\backend\core\engine\log.py", line 38, in info_log
    self.save_log(message, 'INFO')
  File "C:\Users\86135\Desktop\EasyPost\backend\core\engine\log.py", line 13, in save_log
    print(info)
OSError: [Errno 22] Invalid argument

During handling of the above exception, another exception occurred:

Traceback (most recent call last):
  File "C:\Users\86135\AppData\Local\Programs\Python\Python311\Lib\site-packages\apscheduler\executors\base.py", line 125, in run_job
    retval = job.func(*job.args, **job.kwargs)
             ^^^^^^^^^^^^^^^^^^^^^^^^^^^^^^^^^
  File "C:\Users\86135\Desktop\EasyPost\backend\api\dao\https.py", line 404, in run_test_suite
    raise Exception(f"调试测试计划失败: {e}")
Exception: 调试测试计划失败: [Errno 22] Invalid argument
[2024-01-23 11:00:00,055][ThreadPoolExecutor-1_0:16664][task_id:apscheduler.executors.default][base.py:131][ERROR][Job "HttpDao.run_test_suite (trigger: cron[month='*', day='*', day_of_week='*', hour='*', minute='*'], next run at: 2024-01-23 11:01:00 CST)" raised an exception]
Traceback (most recent call last):
  File "C:\Users\86135\Desktop\EasyPost\backend\api\dao\https.py", line 401, in run_test_suite
    result = run_test(case_data)
             ^^^^^^^^^^^^^^^^^^^
  File "C:\Users\86135\Desktop\EasyPost\backend\core\engine\session_runner.py", line 44, in run_test
    suite = GenerateCase().data_to_suite(case_data)
            ^^^^^^^^^^^^^^^^^^^^^^^^^^^^^^^^^^^^^^^
  File "C:\Users\86135\Desktop\EasyPost\backend\core\engine\generate.py", line 28, in data_to_suite
    self.add_test(item, load, suite)
  File "C:\Users\86135\Desktop\EasyPost\backend\core\engine\generate.py", line 36, in add_test
    cls = self.create_test_class(item)
          ^^^^^^^^^^^^^^^^^^^^^^^^^^^^
  File "C:\Users\86135\Desktop\EasyPost\backend\core\engine\generate.py", line 50, in create_test_class
    self.create_case_content(cls, collections)
  File "C:\Users\86135\Desktop\EasyPost\backend\core\engine\generate.py", line 97, in create_case_content
    self.controller.loop(loop_count, cls, test_name, new_test_func)
  File "C:\Users\86135\Desktop\EasyPost\backend\core\engine\base.py", line 61, in loop
    self.info_log('用例第{}次循环\n'.format(c + 1))
  File "C:\Users\86135\Desktop\EasyPost\backend\core\engine\log.py", line 38, in info_log
    self.save_log(message, 'INFO')
  File "C:\Users\86135\Desktop\EasyPost\backend\core\engine\log.py", line 13, in save_log
    print(info)
OSError: [Errno 22] Invalid argument

During handling of the above exception, another exception occurred:

Traceback (most recent call last):
  File "C:\Users\86135\AppData\Local\Programs\Python\Python311\Lib\site-packages\apscheduler\executors\base.py", line 125, in run_job
    retval = job.func(*job.args, **job.kwargs)
             ^^^^^^^^^^^^^^^^^^^^^^^^^^^^^^^^^
  File "C:\Users\86135\Desktop\EasyPost\backend\api\dao\https.py", line 404, in run_test_suite
    raise Exception(f"调试测试计划失败: {e}")
Exception: 调试测试计划失败: [Errno 22] Invalid argument
[2024-01-23 11:01:00,044][ThreadPoolExecutor-1_0:16664][task_id:apscheduler.executors.default][base.py:131][ERROR][Job "HttpDao.run_test_suite (trigger: cron[month='*', day='*', day_of_week='*', hour='*', minute='*'], next run at: 2024-01-23 11:02:00 CST)" raised an exception]
Traceback (most recent call last):
  File "C:\Users\86135\Desktop\EasyPost\backend\api\dao\https.py", line 401, in run_test_suite
    result = run_test(case_data)
             ^^^^^^^^^^^^^^^^^^^
  File "C:\Users\86135\Desktop\EasyPost\backend\core\engine\session_runner.py", line 44, in run_test
    suite = GenerateCase().data_to_suite(case_data)
            ^^^^^^^^^^^^^^^^^^^^^^^^^^^^^^^^^^^^^^^
  File "C:\Users\86135\Desktop\EasyPost\backend\core\engine\generate.py", line 28, in data_to_suite
    self.add_test(item, load, suite)
  File "C:\Users\86135\Desktop\EasyPost\backend\core\engine\generate.py", line 36, in add_test
    cls = self.create_test_class(item)
          ^^^^^^^^^^^^^^^^^^^^^^^^^^^^
  File "C:\Users\86135\Desktop\EasyPost\backend\core\engine\generate.py", line 50, in create_test_class
    self.create_case_content(cls, collections)
  File "C:\Users\86135\Desktop\EasyPost\backend\core\engine\generate.py", line 97, in create_case_content
    self.controller.loop(loop_count, cls, test_name, new_test_func)
  File "C:\Users\86135\Desktop\EasyPost\backend\core\engine\base.py", line 61, in loop
    self.info_log('用例第{}次循环\n'.format(c + 1))
  File "C:\Users\86135\Desktop\EasyPost\backend\core\engine\log.py", line 38, in info_log
    self.save_log(message, 'INFO')
  File "C:\Users\86135\Desktop\EasyPost\backend\core\engine\log.py", line 13, in save_log
    print(info)
OSError: [Errno 22] Invalid argument

During handling of the above exception, another exception occurred:

Traceback (most recent call last):
  File "C:\Users\86135\AppData\Local\Programs\Python\Python311\Lib\site-packages\apscheduler\executors\base.py", line 125, in run_job
    retval = job.func(*job.args, **job.kwargs)
             ^^^^^^^^^^^^^^^^^^^^^^^^^^^^^^^^^
  File "C:\Users\86135\Desktop\EasyPost\backend\api\dao\https.py", line 404, in run_test_suite
    raise Exception(f"调试测试计划失败: {e}")
Exception: 调试测试计划失败: [Errno 22] Invalid argument
[2024-01-23 11:02:00,061][ThreadPoolExecutor-1_0:16664][task_id:apscheduler.executors.default][base.py:131][ERROR][Job "HttpDao.run_test_suite (trigger: cron[month='*', day='*', day_of_week='*', hour='*', minute='*'], next run at: 2024-01-23 11:03:00 CST)" raised an exception]
Traceback (most recent call last):
  File "C:\Users\86135\Desktop\EasyPost\backend\api\dao\https.py", line 401, in run_test_suite
    result = run_test(case_data)
             ^^^^^^^^^^^^^^^^^^^
  File "C:\Users\86135\Desktop\EasyPost\backend\core\engine\session_runner.py", line 44, in run_test
    suite = GenerateCase().data_to_suite(case_data)
            ^^^^^^^^^^^^^^^^^^^^^^^^^^^^^^^^^^^^^^^
  File "C:\Users\86135\Desktop\EasyPost\backend\core\engine\generate.py", line 28, in data_to_suite
    self.add_test(item, load, suite)
  File "C:\Users\86135\Desktop\EasyPost\backend\core\engine\generate.py", line 36, in add_test
    cls = self.create_test_class(item)
          ^^^^^^^^^^^^^^^^^^^^^^^^^^^^
  File "C:\Users\86135\Desktop\EasyPost\backend\core\engine\generate.py", line 50, in create_test_class
    self.create_case_content(cls, collections)
  File "C:\Users\86135\Desktop\EasyPost\backend\core\engine\generate.py", line 97, in create_case_content
    self.controller.loop(loop_count, cls, test_name, new_test_func)
  File "C:\Users\86135\Desktop\EasyPost\backend\core\engine\base.py", line 61, in loop
    self.info_log('用例第{}次循环\n'.format(c + 1))
  File "C:\Users\86135\Desktop\EasyPost\backend\core\engine\log.py", line 38, in info_log
    self.save_log(message, 'INFO')
  File "C:\Users\86135\Desktop\EasyPost\backend\core\engine\log.py", line 13, in save_log
    print(info)
OSError: [Errno 22] Invalid argument

During handling of the above exception, another exception occurred:

Traceback (most recent call last):
  File "C:\Users\86135\AppData\Local\Programs\Python\Python311\Lib\site-packages\apscheduler\executors\base.py", line 125, in run_job
    retval = job.func(*job.args, **job.kwargs)
             ^^^^^^^^^^^^^^^^^^^^^^^^^^^^^^^^^
  File "C:\Users\86135\Desktop\EasyPost\backend\api\dao\https.py", line 404, in run_test_suite
    raise Exception(f"调试测试计划失败: {e}")
Exception: 调试测试计划失败: [Errno 22] Invalid argument
[2024-01-23 11:03:00,053][ThreadPoolExecutor-1_0:16664][task_id:apscheduler.executors.default][base.py:131][ERROR][Job "HttpDao.run_test_suite (trigger: cron[month='*', day='*', day_of_week='*', hour='*', minute='*'], next run at: 2024-01-23 11:04:00 CST)" raised an exception]
Traceback (most recent call last):
  File "C:\Users\86135\Desktop\EasyPost\backend\api\dao\https.py", line 401, in run_test_suite
    result = run_test(case_data)
             ^^^^^^^^^^^^^^^^^^^
  File "C:\Users\86135\Desktop\EasyPost\backend\core\engine\session_runner.py", line 44, in run_test
    suite = GenerateCase().data_to_suite(case_data)
            ^^^^^^^^^^^^^^^^^^^^^^^^^^^^^^^^^^^^^^^
  File "C:\Users\86135\Desktop\EasyPost\backend\core\engine\generate.py", line 28, in data_to_suite
    self.add_test(item, load, suite)
  File "C:\Users\86135\Desktop\EasyPost\backend\core\engine\generate.py", line 36, in add_test
    cls = self.create_test_class(item)
          ^^^^^^^^^^^^^^^^^^^^^^^^^^^^
  File "C:\Users\86135\Desktop\EasyPost\backend\core\engine\generate.py", line 50, in create_test_class
    self.create_case_content(cls, collections)
  File "C:\Users\86135\Desktop\EasyPost\backend\core\engine\generate.py", line 97, in create_case_content
    self.controller.loop(loop_count, cls, test_name, new_test_func)
  File "C:\Users\86135\Desktop\EasyPost\backend\core\engine\base.py", line 61, in loop
    self.info_log('用例第{}次循环\n'.format(c + 1))
  File "C:\Users\86135\Desktop\EasyPost\backend\core\engine\log.py", line 38, in info_log
    self.save_log(message, 'INFO')
  File "C:\Users\86135\Desktop\EasyPost\backend\core\engine\log.py", line 13, in save_log
    print(info)
OSError: [Errno 22] Invalid argument

During handling of the above exception, another exception occurred:

Traceback (most recent call last):
  File "C:\Users\86135\AppData\Local\Programs\Python\Python311\Lib\site-packages\apscheduler\executors\base.py", line 125, in run_job
    retval = job.func(*job.args, **job.kwargs)
             ^^^^^^^^^^^^^^^^^^^^^^^^^^^^^^^^^
  File "C:\Users\86135\Desktop\EasyPost\backend\api\dao\https.py", line 404, in run_test_suite
    raise Exception(f"调试测试计划失败: {e}")
Exception: 调试测试计划失败: [Errno 22] Invalid argument
[2024-01-23 11:04:00,058][ThreadPoolExecutor-1_0:16664][task_id:apscheduler.executors.default][base.py:131][ERROR][Job "HttpDao.run_test_suite (trigger: cron[month='*', day='*', day_of_week='*', hour='*', minute='*'], next run at: 2024-01-23 11:05:00 CST)" raised an exception]
Traceback (most recent call last):
  File "C:\Users\86135\Desktop\EasyPost\backend\api\dao\https.py", line 401, in run_test_suite
    result = run_test(case_data)
             ^^^^^^^^^^^^^^^^^^^
  File "C:\Users\86135\Desktop\EasyPost\backend\core\engine\session_runner.py", line 44, in run_test
    suite = GenerateCase().data_to_suite(case_data)
            ^^^^^^^^^^^^^^^^^^^^^^^^^^^^^^^^^^^^^^^
  File "C:\Users\86135\Desktop\EasyPost\backend\core\engine\generate.py", line 28, in data_to_suite
    self.add_test(item, load, suite)
  File "C:\Users\86135\Desktop\EasyPost\backend\core\engine\generate.py", line 36, in add_test
    cls = self.create_test_class(item)
          ^^^^^^^^^^^^^^^^^^^^^^^^^^^^
  File "C:\Users\86135\Desktop\EasyPost\backend\core\engine\generate.py", line 50, in create_test_class
    self.create_case_content(cls, collections)
  File "C:\Users\86135\Desktop\EasyPost\backend\core\engine\generate.py", line 97, in create_case_content
    self.controller.loop(loop_count, cls, test_name, new_test_func)
  File "C:\Users\86135\Desktop\EasyPost\backend\core\engine\base.py", line 61, in loop
    self.info_log('用例第{}次循环\n'.format(c + 1))
  File "C:\Users\86135\Desktop\EasyPost\backend\core\engine\log.py", line 38, in info_log
    self.save_log(message, 'INFO')
  File "C:\Users\86135\Desktop\EasyPost\backend\core\engine\log.py", line 13, in save_log
    print(info)
OSError: [Errno 22] Invalid argument

During handling of the above exception, another exception occurred:

Traceback (most recent call last):
  File "C:\Users\86135\AppData\Local\Programs\Python\Python311\Lib\site-packages\apscheduler\executors\base.py", line 125, in run_job
    retval = job.func(*job.args, **job.kwargs)
             ^^^^^^^^^^^^^^^^^^^^^^^^^^^^^^^^^
  File "C:\Users\86135\Desktop\EasyPost\backend\api\dao\https.py", line 404, in run_test_suite
    raise Exception(f"调试测试计划失败: {e}")
Exception: 调试测试计划失败: [Errno 22] Invalid argument
[2024-01-23 11:05:00,046][ThreadPoolExecutor-1_0:16664][task_id:apscheduler.executors.default][base.py:131][ERROR][Job "HttpDao.run_test_suite (trigger: cron[month='*', day='*', day_of_week='*', hour='*', minute='*'], next run at: 2024-01-23 11:06:00 CST)" raised an exception]
Traceback (most recent call last):
  File "C:\Users\86135\Desktop\EasyPost\backend\api\dao\https.py", line 401, in run_test_suite
    result = run_test(case_data)
             ^^^^^^^^^^^^^^^^^^^
  File "C:\Users\86135\Desktop\EasyPost\backend\core\engine\session_runner.py", line 44, in run_test
    suite = GenerateCase().data_to_suite(case_data)
            ^^^^^^^^^^^^^^^^^^^^^^^^^^^^^^^^^^^^^^^
  File "C:\Users\86135\Desktop\EasyPost\backend\core\engine\generate.py", line 28, in data_to_suite
    self.add_test(item, load, suite)
  File "C:\Users\86135\Desktop\EasyPost\backend\core\engine\generate.py", line 36, in add_test
    cls = self.create_test_class(item)
          ^^^^^^^^^^^^^^^^^^^^^^^^^^^^
  File "C:\Users\86135\Desktop\EasyPost\backend\core\engine\generate.py", line 50, in create_test_class
    self.create_case_content(cls, collections)
  File "C:\Users\86135\Desktop\EasyPost\backend\core\engine\generate.py", line 97, in create_case_content
    self.controller.loop(loop_count, cls, test_name, new_test_func)
  File "C:\Users\86135\Desktop\EasyPost\backend\core\engine\base.py", line 61, in loop
    self.info_log('用例第{}次循环\n'.format(c + 1))
  File "C:\Users\86135\Desktop\EasyPost\backend\core\engine\log.py", line 38, in info_log
    self.save_log(message, 'INFO')
  File "C:\Users\86135\Desktop\EasyPost\backend\core\engine\log.py", line 13, in save_log
    print(info)
OSError: [Errno 22] Invalid argument

During handling of the above exception, another exception occurred:

Traceback (most recent call last):
  File "C:\Users\86135\AppData\Local\Programs\Python\Python311\Lib\site-packages\apscheduler\executors\base.py", line 125, in run_job
    retval = job.func(*job.args, **job.kwargs)
             ^^^^^^^^^^^^^^^^^^^^^^^^^^^^^^^^^
  File "C:\Users\86135\Desktop\EasyPost\backend\api\dao\https.py", line 404, in run_test_suite
    raise Exception(f"调试测试计划失败: {e}")
Exception: 调试测试计划失败: [Errno 22] Invalid argument
[2024-01-23 11:06:00,053][ThreadPoolExecutor-1_0:16664][task_id:apscheduler.executors.default][base.py:131][ERROR][Job "HttpDao.run_test_suite (trigger: cron[month='*', day='*', day_of_week='*', hour='*', minute='*'], next run at: 2024-01-23 11:07:00 CST)" raised an exception]
Traceback (most recent call last):
  File "C:\Users\86135\Desktop\EasyPost\backend\api\dao\https.py", line 401, in run_test_suite
    result = run_test(case_data)
             ^^^^^^^^^^^^^^^^^^^
  File "C:\Users\86135\Desktop\EasyPost\backend\core\engine\session_runner.py", line 44, in run_test
    suite = GenerateCase().data_to_suite(case_data)
            ^^^^^^^^^^^^^^^^^^^^^^^^^^^^^^^^^^^^^^^
  File "C:\Users\86135\Desktop\EasyPost\backend\core\engine\generate.py", line 28, in data_to_suite
    self.add_test(item, load, suite)
  File "C:\Users\86135\Desktop\EasyPost\backend\core\engine\generate.py", line 36, in add_test
    cls = self.create_test_class(item)
          ^^^^^^^^^^^^^^^^^^^^^^^^^^^^
  File "C:\Users\86135\Desktop\EasyPost\backend\core\engine\generate.py", line 50, in create_test_class
    self.create_case_content(cls, collections)
  File "C:\Users\86135\Desktop\EasyPost\backend\core\engine\generate.py", line 97, in create_case_content
    self.controller.loop(loop_count, cls, test_name, new_test_func)
  File "C:\Users\86135\Desktop\EasyPost\backend\core\engine\base.py", line 61, in loop
    self.info_log('用例第{}次循环\n'.format(c + 1))
  File "C:\Users\86135\Desktop\EasyPost\backend\core\engine\log.py", line 38, in info_log
    self.save_log(message, 'INFO')
  File "C:\Users\86135\Desktop\EasyPost\backend\core\engine\log.py", line 13, in save_log
    print(info)
OSError: [Errno 22] Invalid argument

During handling of the above exception, another exception occurred:

Traceback (most recent call last):
  File "C:\Users\86135\AppData\Local\Programs\Python\Python311\Lib\site-packages\apscheduler\executors\base.py", line 125, in run_job
    retval = job.func(*job.args, **job.kwargs)
             ^^^^^^^^^^^^^^^^^^^^^^^^^^^^^^^^^
  File "C:\Users\86135\Desktop\EasyPost\backend\api\dao\https.py", line 404, in run_test_suite
    raise Exception(f"调试测试计划失败: {e}")
Exception: 调试测试计划失败: [Errno 22] Invalid argument
[2024-01-23 11:07:00,056][ThreadPoolExecutor-1_0:16664][task_id:apscheduler.executors.default][base.py:131][ERROR][Job "HttpDao.run_test_suite (trigger: cron[month='*', day='*', day_of_week='*', hour='*', minute='*'], next run at: 2024-01-23 11:08:00 CST)" raised an exception]
Traceback (most recent call last):
  File "C:\Users\86135\Desktop\EasyPost\backend\api\dao\https.py", line 401, in run_test_suite
    result = run_test(case_data)
             ^^^^^^^^^^^^^^^^^^^
  File "C:\Users\86135\Desktop\EasyPost\backend\core\engine\session_runner.py", line 44, in run_test
    suite = GenerateCase().data_to_suite(case_data)
            ^^^^^^^^^^^^^^^^^^^^^^^^^^^^^^^^^^^^^^^
  File "C:\Users\86135\Desktop\EasyPost\backend\core\engine\generate.py", line 28, in data_to_suite
    self.add_test(item, load, suite)
  File "C:\Users\86135\Desktop\EasyPost\backend\core\engine\generate.py", line 36, in add_test
    cls = self.create_test_class(item)
          ^^^^^^^^^^^^^^^^^^^^^^^^^^^^
  File "C:\Users\86135\Desktop\EasyPost\backend\core\engine\generate.py", line 50, in create_test_class
    self.create_case_content(cls, collections)
  File "C:\Users\86135\Desktop\EasyPost\backend\core\engine\generate.py", line 97, in create_case_content
    self.controller.loop(loop_count, cls, test_name, new_test_func)
  File "C:\Users\86135\Desktop\EasyPost\backend\core\engine\base.py", line 61, in loop
    self.info_log('用例第{}次循环\n'.format(c + 1))
  File "C:\Users\86135\Desktop\EasyPost\backend\core\engine\log.py", line 38, in info_log
    self.save_log(message, 'INFO')
  File "C:\Users\86135\Desktop\EasyPost\backend\core\engine\log.py", line 13, in save_log
    print(info)
OSError: [Errno 22] Invalid argument

During handling of the above exception, another exception occurred:

Traceback (most recent call last):
  File "C:\Users\86135\AppData\Local\Programs\Python\Python311\Lib\site-packages\apscheduler\executors\base.py", line 125, in run_job
    retval = job.func(*job.args, **job.kwargs)
             ^^^^^^^^^^^^^^^^^^^^^^^^^^^^^^^^^
  File "C:\Users\86135\Desktop\EasyPost\backend\api\dao\https.py", line 404, in run_test_suite
    raise Exception(f"调试测试计划失败: {e}")
Exception: 调试测试计划失败: [Errno 22] Invalid argument
[2024-01-23 11:08:00,055][ThreadPoolExecutor-1_0:16664][task_id:apscheduler.executors.default][base.py:131][ERROR][Job "HttpDao.run_test_suite (trigger: cron[month='*', day='*', day_of_week='*', hour='*', minute='*'], next run at: 2024-01-23 11:09:00 CST)" raised an exception]
Traceback (most recent call last):
  File "C:\Users\86135\Desktop\EasyPost\backend\api\dao\https.py", line 401, in run_test_suite
    result = run_test(case_data)
             ^^^^^^^^^^^^^^^^^^^
  File "C:\Users\86135\Desktop\EasyPost\backend\core\engine\session_runner.py", line 44, in run_test
    suite = GenerateCase().data_to_suite(case_data)
            ^^^^^^^^^^^^^^^^^^^^^^^^^^^^^^^^^^^^^^^
  File "C:\Users\86135\Desktop\EasyPost\backend\core\engine\generate.py", line 28, in data_to_suite
    self.add_test(item, load, suite)
  File "C:\Users\86135\Desktop\EasyPost\backend\core\engine\generate.py", line 36, in add_test
    cls = self.create_test_class(item)
          ^^^^^^^^^^^^^^^^^^^^^^^^^^^^
  File "C:\Users\86135\Desktop\EasyPost\backend\core\engine\generate.py", line 50, in create_test_class
    self.create_case_content(cls, collections)
  File "C:\Users\86135\Desktop\EasyPost\backend\core\engine\generate.py", line 97, in create_case_content
    self.controller.loop(loop_count, cls, test_name, new_test_func)
  File "C:\Users\86135\Desktop\EasyPost\backend\core\engine\base.py", line 61, in loop
    self.info_log('用例第{}次循环\n'.format(c + 1))
  File "C:\Users\86135\Desktop\EasyPost\backend\core\engine\log.py", line 38, in info_log
    self.save_log(message, 'INFO')
  File "C:\Users\86135\Desktop\EasyPost\backend\core\engine\log.py", line 13, in save_log
    print(info)
OSError: [Errno 22] Invalid argument

During handling of the above exception, another exception occurred:

Traceback (most recent call last):
  File "C:\Users\86135\AppData\Local\Programs\Python\Python311\Lib\site-packages\apscheduler\executors\base.py", line 125, in run_job
    retval = job.func(*job.args, **job.kwargs)
             ^^^^^^^^^^^^^^^^^^^^^^^^^^^^^^^^^
  File "C:\Users\86135\Desktop\EasyPost\backend\api\dao\https.py", line 404, in run_test_suite
    raise Exception(f"调试测试计划失败: {e}")
Exception: 调试测试计划失败: [Errno 22] Invalid argument
[2024-01-23 11:09:00,051][ThreadPoolExecutor-1_0:16664][task_id:apscheduler.executors.default][base.py:131][ERROR][Job "HttpDao.run_test_suite (trigger: cron[month='*', day='*', day_of_week='*', hour='*', minute='*'], next run at: 2024-01-23 11:10:00 CST)" raised an exception]
Traceback (most recent call last):
  File "C:\Users\86135\Desktop\EasyPost\backend\api\dao\https.py", line 401, in run_test_suite
    result = run_test(case_data)
             ^^^^^^^^^^^^^^^^^^^
  File "C:\Users\86135\Desktop\EasyPost\backend\core\engine\session_runner.py", line 44, in run_test
    suite = GenerateCase().data_to_suite(case_data)
            ^^^^^^^^^^^^^^^^^^^^^^^^^^^^^^^^^^^^^^^
  File "C:\Users\86135\Desktop\EasyPost\backend\core\engine\generate.py", line 28, in data_to_suite
    self.add_test(item, load, suite)
  File "C:\Users\86135\Desktop\EasyPost\backend\core\engine\generate.py", line 36, in add_test
    cls = self.create_test_class(item)
          ^^^^^^^^^^^^^^^^^^^^^^^^^^^^
  File "C:\Users\86135\Desktop\EasyPost\backend\core\engine\generate.py", line 50, in create_test_class
    self.create_case_content(cls, collections)
  File "C:\Users\86135\Desktop\EasyPost\backend\core\engine\generate.py", line 97, in create_case_content
    self.controller.loop(loop_count, cls, test_name, new_test_func)
  File "C:\Users\86135\Desktop\EasyPost\backend\core\engine\base.py", line 61, in loop
    self.info_log('用例第{}次循环\n'.format(c + 1))
  File "C:\Users\86135\Desktop\EasyPost\backend\core\engine\log.py", line 38, in info_log
    self.save_log(message, 'INFO')
  File "C:\Users\86135\Desktop\EasyPost\backend\core\engine\log.py", line 13, in save_log
    print(info)
OSError: [Errno 22] Invalid argument

During handling of the above exception, another exception occurred:

Traceback (most recent call last):
  File "C:\Users\86135\AppData\Local\Programs\Python\Python311\Lib\site-packages\apscheduler\executors\base.py", line 125, in run_job
    retval = job.func(*job.args, **job.kwargs)
             ^^^^^^^^^^^^^^^^^^^^^^^^^^^^^^^^^
  File "C:\Users\86135\Desktop\EasyPost\backend\api\dao\https.py", line 404, in run_test_suite
    raise Exception(f"调试测试计划失败: {e}")
Exception: 调试测试计划失败: [Errno 22] Invalid argument
[2024-01-23 11:10:00,042][ThreadPoolExecutor-1_0:16664][task_id:apscheduler.executors.default][base.py:131][ERROR][Job "HttpDao.run_test_suite (trigger: cron[month='*', day='*', day_of_week='*', hour='*', minute='*'], next run at: 2024-01-23 11:11:00 CST)" raised an exception]
Traceback (most recent call last):
  File "C:\Users\86135\Desktop\EasyPost\backend\api\dao\https.py", line 401, in run_test_suite
    result = run_test(case_data)
             ^^^^^^^^^^^^^^^^^^^
  File "C:\Users\86135\Desktop\EasyPost\backend\core\engine\session_runner.py", line 44, in run_test
    suite = GenerateCase().data_to_suite(case_data)
            ^^^^^^^^^^^^^^^^^^^^^^^^^^^^^^^^^^^^^^^
  File "C:\Users\86135\Desktop\EasyPost\backend\core\engine\generate.py", line 28, in data_to_suite
    self.add_test(item, load, suite)
  File "C:\Users\86135\Desktop\EasyPost\backend\core\engine\generate.py", line 36, in add_test
    cls = self.create_test_class(item)
          ^^^^^^^^^^^^^^^^^^^^^^^^^^^^
  File "C:\Users\86135\Desktop\EasyPost\backend\core\engine\generate.py", line 50, in create_test_class
    self.create_case_content(cls, collections)
  File "C:\Users\86135\Desktop\EasyPost\backend\core\engine\generate.py", line 97, in create_case_content
    self.controller.loop(loop_count, cls, test_name, new_test_func)
  File "C:\Users\86135\Desktop\EasyPost\backend\core\engine\base.py", line 61, in loop
    self.info_log('用例第{}次循环\n'.format(c + 1))
  File "C:\Users\86135\Desktop\EasyPost\backend\core\engine\log.py", line 38, in info_log
    self.save_log(message, 'INFO')
  File "C:\Users\86135\Desktop\EasyPost\backend\core\engine\log.py", line 13, in save_log
    print(info)
OSError: [Errno 22] Invalid argument

During handling of the above exception, another exception occurred:

Traceback (most recent call last):
  File "C:\Users\86135\AppData\Local\Programs\Python\Python311\Lib\site-packages\apscheduler\executors\base.py", line 125, in run_job
    retval = job.func(*job.args, **job.kwargs)
             ^^^^^^^^^^^^^^^^^^^^^^^^^^^^^^^^^
  File "C:\Users\86135\Desktop\EasyPost\backend\api\dao\https.py", line 404, in run_test_suite
    raise Exception(f"调试测试计划失败: {e}")
Exception: 调试测试计划失败: [Errno 22] Invalid argument
[2024-01-23 11:11:00,043][ThreadPoolExecutor-1_0:16664][task_id:apscheduler.executors.default][base.py:131][ERROR][Job "HttpDao.run_test_suite (trigger: cron[month='*', day='*', day_of_week='*', hour='*', minute='*'], next run at: 2024-01-23 11:12:00 CST)" raised an exception]
Traceback (most recent call last):
  File "C:\Users\86135\Desktop\EasyPost\backend\api\dao\https.py", line 401, in run_test_suite
    result = run_test(case_data)
             ^^^^^^^^^^^^^^^^^^^
  File "C:\Users\86135\Desktop\EasyPost\backend\core\engine\session_runner.py", line 44, in run_test
    suite = GenerateCase().data_to_suite(case_data)
            ^^^^^^^^^^^^^^^^^^^^^^^^^^^^^^^^^^^^^^^
  File "C:\Users\86135\Desktop\EasyPost\backend\core\engine\generate.py", line 28, in data_to_suite
    self.add_test(item, load, suite)
  File "C:\Users\86135\Desktop\EasyPost\backend\core\engine\generate.py", line 36, in add_test
    cls = self.create_test_class(item)
          ^^^^^^^^^^^^^^^^^^^^^^^^^^^^
  File "C:\Users\86135\Desktop\EasyPost\backend\core\engine\generate.py", line 50, in create_test_class
    self.create_case_content(cls, collections)
  File "C:\Users\86135\Desktop\EasyPost\backend\core\engine\generate.py", line 97, in create_case_content
    self.controller.loop(loop_count, cls, test_name, new_test_func)
  File "C:\Users\86135\Desktop\EasyPost\backend\core\engine\base.py", line 61, in loop
    self.info_log('用例第{}次循环\n'.format(c + 1))
  File "C:\Users\86135\Desktop\EasyPost\backend\core\engine\log.py", line 38, in info_log
    self.save_log(message, 'INFO')
  File "C:\Users\86135\Desktop\EasyPost\backend\core\engine\log.py", line 13, in save_log
    print(info)
OSError: [Errno 22] Invalid argument

During handling of the above exception, another exception occurred:

Traceback (most recent call last):
  File "C:\Users\86135\AppData\Local\Programs\Python\Python311\Lib\site-packages\apscheduler\executors\base.py", line 125, in run_job
    retval = job.func(*job.args, **job.kwargs)
             ^^^^^^^^^^^^^^^^^^^^^^^^^^^^^^^^^
  File "C:\Users\86135\Desktop\EasyPost\backend\api\dao\https.py", line 404, in run_test_suite
    raise Exception(f"调试测试计划失败: {e}")
Exception: 调试测试计划失败: [Errno 22] Invalid argument
[2024-01-23 11:12:00,049][ThreadPoolExecutor-1_0:16664][task_id:apscheduler.executors.default][base.py:131][ERROR][Job "HttpDao.run_test_suite (trigger: cron[month='*', day='*', day_of_week='*', hour='*', minute='*'], next run at: 2024-01-23 11:13:00 CST)" raised an exception]
Traceback (most recent call last):
  File "C:\Users\86135\Desktop\EasyPost\backend\api\dao\https.py", line 401, in run_test_suite
    result = run_test(case_data)
             ^^^^^^^^^^^^^^^^^^^
  File "C:\Users\86135\Desktop\EasyPost\backend\core\engine\session_runner.py", line 44, in run_test
    suite = GenerateCase().data_to_suite(case_data)
            ^^^^^^^^^^^^^^^^^^^^^^^^^^^^^^^^^^^^^^^
  File "C:\Users\86135\Desktop\EasyPost\backend\core\engine\generate.py", line 28, in data_to_suite
    self.add_test(item, load, suite)
  File "C:\Users\86135\Desktop\EasyPost\backend\core\engine\generate.py", line 36, in add_test
    cls = self.create_test_class(item)
          ^^^^^^^^^^^^^^^^^^^^^^^^^^^^
  File "C:\Users\86135\Desktop\EasyPost\backend\core\engine\generate.py", line 50, in create_test_class
    self.create_case_content(cls, collections)
  File "C:\Users\86135\Desktop\EasyPost\backend\core\engine\generate.py", line 97, in create_case_content
    self.controller.loop(loop_count, cls, test_name, new_test_func)
  File "C:\Users\86135\Desktop\EasyPost\backend\core\engine\base.py", line 61, in loop
    self.info_log('用例第{}次循环\n'.format(c + 1))
  File "C:\Users\86135\Desktop\EasyPost\backend\core\engine\log.py", line 38, in info_log
    self.save_log(message, 'INFO')
  File "C:\Users\86135\Desktop\EasyPost\backend\core\engine\log.py", line 13, in save_log
    print(info)
OSError: [Errno 22] Invalid argument

During handling of the above exception, another exception occurred:

Traceback (most recent call last):
  File "C:\Users\86135\AppData\Local\Programs\Python\Python311\Lib\site-packages\apscheduler\executors\base.py", line 125, in run_job
    retval = job.func(*job.args, **job.kwargs)
             ^^^^^^^^^^^^^^^^^^^^^^^^^^^^^^^^^
  File "C:\Users\86135\Desktop\EasyPost\backend\api\dao\https.py", line 404, in run_test_suite
    raise Exception(f"调试测试计划失败: {e}")
Exception: 调试测试计划失败: [Errno 22] Invalid argument
[2024-01-23 11:13:00,045][ThreadPoolExecutor-1_0:16664][task_id:apscheduler.executors.default][base.py:131][ERROR][Job "HttpDao.run_test_suite (trigger: cron[month='*', day='*', day_of_week='*', hour='*', minute='*'], next run at: 2024-01-23 11:14:00 CST)" raised an exception]
Traceback (most recent call last):
  File "C:\Users\86135\Desktop\EasyPost\backend\api\dao\https.py", line 401, in run_test_suite
    result = run_test(case_data)
             ^^^^^^^^^^^^^^^^^^^
  File "C:\Users\86135\Desktop\EasyPost\backend\core\engine\session_runner.py", line 44, in run_test
    suite = GenerateCase().data_to_suite(case_data)
            ^^^^^^^^^^^^^^^^^^^^^^^^^^^^^^^^^^^^^^^
  File "C:\Users\86135\Desktop\EasyPost\backend\core\engine\generate.py", line 28, in data_to_suite
    self.add_test(item, load, suite)
  File "C:\Users\86135\Desktop\EasyPost\backend\core\engine\generate.py", line 36, in add_test
    cls = self.create_test_class(item)
          ^^^^^^^^^^^^^^^^^^^^^^^^^^^^
  File "C:\Users\86135\Desktop\EasyPost\backend\core\engine\generate.py", line 50, in create_test_class
    self.create_case_content(cls, collections)
  File "C:\Users\86135\Desktop\EasyPost\backend\core\engine\generate.py", line 97, in create_case_content
    self.controller.loop(loop_count, cls, test_name, new_test_func)
  File "C:\Users\86135\Desktop\EasyPost\backend\core\engine\base.py", line 61, in loop
    self.info_log('用例第{}次循环\n'.format(c + 1))
  File "C:\Users\86135\Desktop\EasyPost\backend\core\engine\log.py", line 38, in info_log
    self.save_log(message, 'INFO')
  File "C:\Users\86135\Desktop\EasyPost\backend\core\engine\log.py", line 13, in save_log
    print(info)
OSError: [Errno 22] Invalid argument

During handling of the above exception, another exception occurred:

Traceback (most recent call last):
  File "C:\Users\86135\AppData\Local\Programs\Python\Python311\Lib\site-packages\apscheduler\executors\base.py", line 125, in run_job
    retval = job.func(*job.args, **job.kwargs)
             ^^^^^^^^^^^^^^^^^^^^^^^^^^^^^^^^^
  File "C:\Users\86135\Desktop\EasyPost\backend\api\dao\https.py", line 404, in run_test_suite
    raise Exception(f"调试测试计划失败: {e}")
Exception: 调试测试计划失败: [Errno 22] Invalid argument
[2024-01-23 11:14:00,050][ThreadPoolExecutor-1_0:16664][task_id:apscheduler.executors.default][base.py:131][ERROR][Job "HttpDao.run_test_suite (trigger: cron[month='*', day='*', day_of_week='*', hour='*', minute='*'], next run at: 2024-01-23 11:15:00 CST)" raised an exception]
Traceback (most recent call last):
  File "C:\Users\86135\Desktop\EasyPost\backend\api\dao\https.py", line 401, in run_test_suite
    result = run_test(case_data)
             ^^^^^^^^^^^^^^^^^^^
  File "C:\Users\86135\Desktop\EasyPost\backend\core\engine\session_runner.py", line 44, in run_test
    suite = GenerateCase().data_to_suite(case_data)
            ^^^^^^^^^^^^^^^^^^^^^^^^^^^^^^^^^^^^^^^
  File "C:\Users\86135\Desktop\EasyPost\backend\core\engine\generate.py", line 28, in data_to_suite
    self.add_test(item, load, suite)
  File "C:\Users\86135\Desktop\EasyPost\backend\core\engine\generate.py", line 36, in add_test
    cls = self.create_test_class(item)
          ^^^^^^^^^^^^^^^^^^^^^^^^^^^^
  File "C:\Users\86135\Desktop\EasyPost\backend\core\engine\generate.py", line 50, in create_test_class
    self.create_case_content(cls, collections)
  File "C:\Users\86135\Desktop\EasyPost\backend\core\engine\generate.py", line 97, in create_case_content
    self.controller.loop(loop_count, cls, test_name, new_test_func)
  File "C:\Users\86135\Desktop\EasyPost\backend\core\engine\base.py", line 61, in loop
    self.info_log('用例第{}次循环\n'.format(c + 1))
  File "C:\Users\86135\Desktop\EasyPost\backend\core\engine\log.py", line 38, in info_log
    self.save_log(message, 'INFO')
  File "C:\Users\86135\Desktop\EasyPost\backend\core\engine\log.py", line 13, in save_log
    print(info)
OSError: [Errno 22] Invalid argument

During handling of the above exception, another exception occurred:

Traceback (most recent call last):
  File "C:\Users\86135\AppData\Local\Programs\Python\Python311\Lib\site-packages\apscheduler\executors\base.py", line 125, in run_job
    retval = job.func(*job.args, **job.kwargs)
             ^^^^^^^^^^^^^^^^^^^^^^^^^^^^^^^^^
  File "C:\Users\86135\Desktop\EasyPost\backend\api\dao\https.py", line 404, in run_test_suite
    raise Exception(f"调试测试计划失败: {e}")
Exception: 调试测试计划失败: [Errno 22] Invalid argument
[2024-01-23 11:15:00,053][ThreadPoolExecutor-1_0:16664][task_id:apscheduler.executors.default][base.py:131][ERROR][Job "HttpDao.run_test_suite (trigger: cron[month='*', day='*', day_of_week='*', hour='*', minute='*'], next run at: 2024-01-23 11:16:00 CST)" raised an exception]
Traceback (most recent call last):
  File "C:\Users\86135\Desktop\EasyPost\backend\api\dao\https.py", line 401, in run_test_suite
    result = run_test(case_data)
             ^^^^^^^^^^^^^^^^^^^
  File "C:\Users\86135\Desktop\EasyPost\backend\core\engine\session_runner.py", line 44, in run_test
    suite = GenerateCase().data_to_suite(case_data)
            ^^^^^^^^^^^^^^^^^^^^^^^^^^^^^^^^^^^^^^^
  File "C:\Users\86135\Desktop\EasyPost\backend\core\engine\generate.py", line 28, in data_to_suite
    self.add_test(item, load, suite)
  File "C:\Users\86135\Desktop\EasyPost\backend\core\engine\generate.py", line 36, in add_test
    cls = self.create_test_class(item)
          ^^^^^^^^^^^^^^^^^^^^^^^^^^^^
  File "C:\Users\86135\Desktop\EasyPost\backend\core\engine\generate.py", line 50, in create_test_class
    self.create_case_content(cls, collections)
  File "C:\Users\86135\Desktop\EasyPost\backend\core\engine\generate.py", line 97, in create_case_content
    self.controller.loop(loop_count, cls, test_name, new_test_func)
  File "C:\Users\86135\Desktop\EasyPost\backend\core\engine\base.py", line 61, in loop
    self.info_log('用例第{}次循环\n'.format(c + 1))
  File "C:\Users\86135\Desktop\EasyPost\backend\core\engine\log.py", line 38, in info_log
    self.save_log(message, 'INFO')
  File "C:\Users\86135\Desktop\EasyPost\backend\core\engine\log.py", line 13, in save_log
    print(info)
OSError: [Errno 22] Invalid argument

During handling of the above exception, another exception occurred:

Traceback (most recent call last):
  File "C:\Users\86135\AppData\Local\Programs\Python\Python311\Lib\site-packages\apscheduler\executors\base.py", line 125, in run_job
    retval = job.func(*job.args, **job.kwargs)
             ^^^^^^^^^^^^^^^^^^^^^^^^^^^^^^^^^
  File "C:\Users\86135\Desktop\EasyPost\backend\api\dao\https.py", line 404, in run_test_suite
    raise Exception(f"调试测试计划失败: {e}")
Exception: 调试测试计划失败: [Errno 22] Invalid argument
[2024-01-23 11:16:00,050][ThreadPoolExecutor-1_0:16664][task_id:apscheduler.executors.default][base.py:131][ERROR][Job "HttpDao.run_test_suite (trigger: cron[month='*', day='*', day_of_week='*', hour='*', minute='*'], next run at: 2024-01-23 11:17:00 CST)" raised an exception]
Traceback (most recent call last):
  File "C:\Users\86135\Desktop\EasyPost\backend\api\dao\https.py", line 401, in run_test_suite
    result = run_test(case_data)
             ^^^^^^^^^^^^^^^^^^^
  File "C:\Users\86135\Desktop\EasyPost\backend\core\engine\session_runner.py", line 44, in run_test
    suite = GenerateCase().data_to_suite(case_data)
            ^^^^^^^^^^^^^^^^^^^^^^^^^^^^^^^^^^^^^^^
  File "C:\Users\86135\Desktop\EasyPost\backend\core\engine\generate.py", line 28, in data_to_suite
    self.add_test(item, load, suite)
  File "C:\Users\86135\Desktop\EasyPost\backend\core\engine\generate.py", line 36, in add_test
    cls = self.create_test_class(item)
          ^^^^^^^^^^^^^^^^^^^^^^^^^^^^
  File "C:\Users\86135\Desktop\EasyPost\backend\core\engine\generate.py", line 50, in create_test_class
    self.create_case_content(cls, collections)
  File "C:\Users\86135\Desktop\EasyPost\backend\core\engine\generate.py", line 97, in create_case_content
    self.controller.loop(loop_count, cls, test_name, new_test_func)
  File "C:\Users\86135\Desktop\EasyPost\backend\core\engine\base.py", line 61, in loop
    self.info_log('用例第{}次循环\n'.format(c + 1))
  File "C:\Users\86135\Desktop\EasyPost\backend\core\engine\log.py", line 38, in info_log
    self.save_log(message, 'INFO')
  File "C:\Users\86135\Desktop\EasyPost\backend\core\engine\log.py", line 13, in save_log
    print(info)
OSError: [Errno 22] Invalid argument

During handling of the above exception, another exception occurred:

Traceback (most recent call last):
  File "C:\Users\86135\AppData\Local\Programs\Python\Python311\Lib\site-packages\apscheduler\executors\base.py", line 125, in run_job
    retval = job.func(*job.args, **job.kwargs)
             ^^^^^^^^^^^^^^^^^^^^^^^^^^^^^^^^^
  File "C:\Users\86135\Desktop\EasyPost\backend\api\dao\https.py", line 404, in run_test_suite
    raise Exception(f"调试测试计划失败: {e}")
Exception: 调试测试计划失败: [Errno 22] Invalid argument
[2024-01-23 11:17:00,051][ThreadPoolExecutor-1_0:16664][task_id:apscheduler.executors.default][base.py:131][ERROR][Job "HttpDao.run_test_suite (trigger: cron[month='*', day='*', day_of_week='*', hour='*', minute='*'], next run at: 2024-01-23 11:18:00 CST)" raised an exception]
Traceback (most recent call last):
  File "C:\Users\86135\Desktop\EasyPost\backend\api\dao\https.py", line 401, in run_test_suite
    result = run_test(case_data)
             ^^^^^^^^^^^^^^^^^^^
  File "C:\Users\86135\Desktop\EasyPost\backend\core\engine\session_runner.py", line 44, in run_test
    suite = GenerateCase().data_to_suite(case_data)
            ^^^^^^^^^^^^^^^^^^^^^^^^^^^^^^^^^^^^^^^
  File "C:\Users\86135\Desktop\EasyPost\backend\core\engine\generate.py", line 28, in data_to_suite
    self.add_test(item, load, suite)
  File "C:\Users\86135\Desktop\EasyPost\backend\core\engine\generate.py", line 36, in add_test
    cls = self.create_test_class(item)
          ^^^^^^^^^^^^^^^^^^^^^^^^^^^^
  File "C:\Users\86135\Desktop\EasyPost\backend\core\engine\generate.py", line 50, in create_test_class
    self.create_case_content(cls, collections)
  File "C:\Users\86135\Desktop\EasyPost\backend\core\engine\generate.py", line 97, in create_case_content
    self.controller.loop(loop_count, cls, test_name, new_test_func)
  File "C:\Users\86135\Desktop\EasyPost\backend\core\engine\base.py", line 61, in loop
    self.info_log('用例第{}次循环\n'.format(c + 1))
  File "C:\Users\86135\Desktop\EasyPost\backend\core\engine\log.py", line 38, in info_log
    self.save_log(message, 'INFO')
  File "C:\Users\86135\Desktop\EasyPost\backend\core\engine\log.py", line 13, in save_log
    print(info)
OSError: [Errno 22] Invalid argument

During handling of the above exception, another exception occurred:

Traceback (most recent call last):
  File "C:\Users\86135\AppData\Local\Programs\Python\Python311\Lib\site-packages\apscheduler\executors\base.py", line 125, in run_job
    retval = job.func(*job.args, **job.kwargs)
             ^^^^^^^^^^^^^^^^^^^^^^^^^^^^^^^^^
  File "C:\Users\86135\Desktop\EasyPost\backend\api\dao\https.py", line 404, in run_test_suite
    raise Exception(f"调试测试计划失败: {e}")
Exception: 调试测试计划失败: [Errno 22] Invalid argument
[2024-01-23 11:18:00,041][ThreadPoolExecutor-1_0:16664][task_id:apscheduler.executors.default][base.py:131][ERROR][Job "HttpDao.run_test_suite (trigger: cron[month='*', day='*', day_of_week='*', hour='*', minute='*'], next run at: 2024-01-23 11:19:00 CST)" raised an exception]
Traceback (most recent call last):
  File "C:\Users\86135\Desktop\EasyPost\backend\api\dao\https.py", line 401, in run_test_suite
    result = run_test(case_data)
             ^^^^^^^^^^^^^^^^^^^
  File "C:\Users\86135\Desktop\EasyPost\backend\core\engine\session_runner.py", line 44, in run_test
    suite = GenerateCase().data_to_suite(case_data)
            ^^^^^^^^^^^^^^^^^^^^^^^^^^^^^^^^^^^^^^^
  File "C:\Users\86135\Desktop\EasyPost\backend\core\engine\generate.py", line 28, in data_to_suite
    self.add_test(item, load, suite)
  File "C:\Users\86135\Desktop\EasyPost\backend\core\engine\generate.py", line 36, in add_test
    cls = self.create_test_class(item)
          ^^^^^^^^^^^^^^^^^^^^^^^^^^^^
  File "C:\Users\86135\Desktop\EasyPost\backend\core\engine\generate.py", line 50, in create_test_class
    self.create_case_content(cls, collections)
  File "C:\Users\86135\Desktop\EasyPost\backend\core\engine\generate.py", line 97, in create_case_content
    self.controller.loop(loop_count, cls, test_name, new_test_func)
  File "C:\Users\86135\Desktop\EasyPost\backend\core\engine\base.py", line 61, in loop
    self.info_log('用例第{}次循环\n'.format(c + 1))
  File "C:\Users\86135\Desktop\EasyPost\backend\core\engine\log.py", line 38, in info_log
    self.save_log(message, 'INFO')
  File "C:\Users\86135\Desktop\EasyPost\backend\core\engine\log.py", line 13, in save_log
    print(info)
OSError: [Errno 22] Invalid argument

During handling of the above exception, another exception occurred:

Traceback (most recent call last):
  File "C:\Users\86135\AppData\Local\Programs\Python\Python311\Lib\site-packages\apscheduler\executors\base.py", line 125, in run_job
    retval = job.func(*job.args, **job.kwargs)
             ^^^^^^^^^^^^^^^^^^^^^^^^^^^^^^^^^
  File "C:\Users\86135\Desktop\EasyPost\backend\api\dao\https.py", line 404, in run_test_suite
    raise Exception(f"调试测试计划失败: {e}")
Exception: 调试测试计划失败: [Errno 22] Invalid argument
[2024-01-23 11:19:00,049][ThreadPoolExecutor-1_0:16664][task_id:apscheduler.executors.default][base.py:131][ERROR][Job "HttpDao.run_test_suite (trigger: cron[month='*', day='*', day_of_week='*', hour='*', minute='*'], next run at: 2024-01-23 11:20:00 CST)" raised an exception]
Traceback (most recent call last):
  File "C:\Users\86135\Desktop\EasyPost\backend\api\dao\https.py", line 401, in run_test_suite
    result = run_test(case_data)
             ^^^^^^^^^^^^^^^^^^^
  File "C:\Users\86135\Desktop\EasyPost\backend\core\engine\session_runner.py", line 44, in run_test
    suite = GenerateCase().data_to_suite(case_data)
            ^^^^^^^^^^^^^^^^^^^^^^^^^^^^^^^^^^^^^^^
  File "C:\Users\86135\Desktop\EasyPost\backend\core\engine\generate.py", line 28, in data_to_suite
    self.add_test(item, load, suite)
  File "C:\Users\86135\Desktop\EasyPost\backend\core\engine\generate.py", line 36, in add_test
    cls = self.create_test_class(item)
          ^^^^^^^^^^^^^^^^^^^^^^^^^^^^
  File "C:\Users\86135\Desktop\EasyPost\backend\core\engine\generate.py", line 50, in create_test_class
    self.create_case_content(cls, collections)
  File "C:\Users\86135\Desktop\EasyPost\backend\core\engine\generate.py", line 97, in create_case_content
    self.controller.loop(loop_count, cls, test_name, new_test_func)
  File "C:\Users\86135\Desktop\EasyPost\backend\core\engine\base.py", line 61, in loop
    self.info_log('用例第{}次循环\n'.format(c + 1))
  File "C:\Users\86135\Desktop\EasyPost\backend\core\engine\log.py", line 38, in info_log
    self.save_log(message, 'INFO')
  File "C:\Users\86135\Desktop\EasyPost\backend\core\engine\log.py", line 13, in save_log
    print(info)
OSError: [Errno 22] Invalid argument

During handling of the above exception, another exception occurred:

Traceback (most recent call last):
  File "C:\Users\86135\AppData\Local\Programs\Python\Python311\Lib\site-packages\apscheduler\executors\base.py", line 125, in run_job
    retval = job.func(*job.args, **job.kwargs)
             ^^^^^^^^^^^^^^^^^^^^^^^^^^^^^^^^^
  File "C:\Users\86135\Desktop\EasyPost\backend\api\dao\https.py", line 404, in run_test_suite
    raise Exception(f"调试测试计划失败: {e}")
Exception: 调试测试计划失败: [Errno 22] Invalid argument
[2024-01-23 11:20:00,055][ThreadPoolExecutor-1_0:16664][task_id:apscheduler.executors.default][base.py:131][ERROR][Job "HttpDao.run_test_suite (trigger: cron[month='*', day='*', day_of_week='*', hour='*', minute='*'], next run at: 2024-01-23 11:21:00 CST)" raised an exception]
Traceback (most recent call last):
  File "C:\Users\86135\Desktop\EasyPost\backend\api\dao\https.py", line 401, in run_test_suite
    result = run_test(case_data)
             ^^^^^^^^^^^^^^^^^^^
  File "C:\Users\86135\Desktop\EasyPost\backend\core\engine\session_runner.py", line 44, in run_test
    suite = GenerateCase().data_to_suite(case_data)
            ^^^^^^^^^^^^^^^^^^^^^^^^^^^^^^^^^^^^^^^
  File "C:\Users\86135\Desktop\EasyPost\backend\core\engine\generate.py", line 28, in data_to_suite
    self.add_test(item, load, suite)
  File "C:\Users\86135\Desktop\EasyPost\backend\core\engine\generate.py", line 36, in add_test
    cls = self.create_test_class(item)
          ^^^^^^^^^^^^^^^^^^^^^^^^^^^^
  File "C:\Users\86135\Desktop\EasyPost\backend\core\engine\generate.py", line 50, in create_test_class
    self.create_case_content(cls, collections)
  File "C:\Users\86135\Desktop\EasyPost\backend\core\engine\generate.py", line 97, in create_case_content
    self.controller.loop(loop_count, cls, test_name, new_test_func)
  File "C:\Users\86135\Desktop\EasyPost\backend\core\engine\base.py", line 61, in loop
    self.info_log('用例第{}次循环\n'.format(c + 1))
  File "C:\Users\86135\Desktop\EasyPost\backend\core\engine\log.py", line 38, in info_log
    self.save_log(message, 'INFO')
  File "C:\Users\86135\Desktop\EasyPost\backend\core\engine\log.py", line 13, in save_log
    print(info)
OSError: [Errno 22] Invalid argument

During handling of the above exception, another exception occurred:

Traceback (most recent call last):
  File "C:\Users\86135\AppData\Local\Programs\Python\Python311\Lib\site-packages\apscheduler\executors\base.py", line 125, in run_job
    retval = job.func(*job.args, **job.kwargs)
             ^^^^^^^^^^^^^^^^^^^^^^^^^^^^^^^^^
  File "C:\Users\86135\Desktop\EasyPost\backend\api\dao\https.py", line 404, in run_test_suite
    raise Exception(f"调试测试计划失败: {e}")
Exception: 调试测试计划失败: [Errno 22] Invalid argument
[2024-01-23 11:21:00,052][ThreadPoolExecutor-1_0:16664][task_id:apscheduler.executors.default][base.py:131][ERROR][Job "HttpDao.run_test_suite (trigger: cron[month='*', day='*', day_of_week='*', hour='*', minute='*'], next run at: 2024-01-23 11:22:00 CST)" raised an exception]
Traceback (most recent call last):
  File "C:\Users\86135\Desktop\EasyPost\backend\api\dao\https.py", line 401, in run_test_suite
    result = run_test(case_data)
             ^^^^^^^^^^^^^^^^^^^
  File "C:\Users\86135\Desktop\EasyPost\backend\core\engine\session_runner.py", line 44, in run_test
    suite = GenerateCase().data_to_suite(case_data)
            ^^^^^^^^^^^^^^^^^^^^^^^^^^^^^^^^^^^^^^^
  File "C:\Users\86135\Desktop\EasyPost\backend\core\engine\generate.py", line 28, in data_to_suite
    self.add_test(item, load, suite)
  File "C:\Users\86135\Desktop\EasyPost\backend\core\engine\generate.py", line 36, in add_test
    cls = self.create_test_class(item)
          ^^^^^^^^^^^^^^^^^^^^^^^^^^^^
  File "C:\Users\86135\Desktop\EasyPost\backend\core\engine\generate.py", line 50, in create_test_class
    self.create_case_content(cls, collections)
  File "C:\Users\86135\Desktop\EasyPost\backend\core\engine\generate.py", line 97, in create_case_content
    self.controller.loop(loop_count, cls, test_name, new_test_func)
  File "C:\Users\86135\Desktop\EasyPost\backend\core\engine\base.py", line 61, in loop
    self.info_log('用例第{}次循环\n'.format(c + 1))
  File "C:\Users\86135\Desktop\EasyPost\backend\core\engine\log.py", line 38, in info_log
    self.save_log(message, 'INFO')
  File "C:\Users\86135\Desktop\EasyPost\backend\core\engine\log.py", line 13, in save_log
    print(info)
OSError: [Errno 22] Invalid argument

During handling of the above exception, another exception occurred:

Traceback (most recent call last):
  File "C:\Users\86135\AppData\Local\Programs\Python\Python311\Lib\site-packages\apscheduler\executors\base.py", line 125, in run_job
    retval = job.func(*job.args, **job.kwargs)
             ^^^^^^^^^^^^^^^^^^^^^^^^^^^^^^^^^
  File "C:\Users\86135\Desktop\EasyPost\backend\api\dao\https.py", line 404, in run_test_suite
    raise Exception(f"调试测试计划失败: {e}")
Exception: 调试测试计划失败: [Errno 22] Invalid argument
[2024-01-23 11:22:00,059][ThreadPoolExecutor-1_0:16664][task_id:apscheduler.executors.default][base.py:131][ERROR][Job "HttpDao.run_test_suite (trigger: cron[month='*', day='*', day_of_week='*', hour='*', minute='*'], next run at: 2024-01-23 11:23:00 CST)" raised an exception]
Traceback (most recent call last):
  File "C:\Users\86135\Desktop\EasyPost\backend\api\dao\https.py", line 401, in run_test_suite
    result = run_test(case_data)
             ^^^^^^^^^^^^^^^^^^^
  File "C:\Users\86135\Desktop\EasyPost\backend\core\engine\session_runner.py", line 44, in run_test
    suite = GenerateCase().data_to_suite(case_data)
            ^^^^^^^^^^^^^^^^^^^^^^^^^^^^^^^^^^^^^^^
  File "C:\Users\86135\Desktop\EasyPost\backend\core\engine\generate.py", line 28, in data_to_suite
    self.add_test(item, load, suite)
  File "C:\Users\86135\Desktop\EasyPost\backend\core\engine\generate.py", line 36, in add_test
    cls = self.create_test_class(item)
          ^^^^^^^^^^^^^^^^^^^^^^^^^^^^
  File "C:\Users\86135\Desktop\EasyPost\backend\core\engine\generate.py", line 50, in create_test_class
    self.create_case_content(cls, collections)
  File "C:\Users\86135\Desktop\EasyPost\backend\core\engine\generate.py", line 97, in create_case_content
    self.controller.loop(loop_count, cls, test_name, new_test_func)
  File "C:\Users\86135\Desktop\EasyPost\backend\core\engine\base.py", line 61, in loop
    self.info_log('用例第{}次循环\n'.format(c + 1))
  File "C:\Users\86135\Desktop\EasyPost\backend\core\engine\log.py", line 38, in info_log
    self.save_log(message, 'INFO')
  File "C:\Users\86135\Desktop\EasyPost\backend\core\engine\log.py", line 13, in save_log
    print(info)
OSError: [Errno 22] Invalid argument

During handling of the above exception, another exception occurred:

Traceback (most recent call last):
  File "C:\Users\86135\AppData\Local\Programs\Python\Python311\Lib\site-packages\apscheduler\executors\base.py", line 125, in run_job
    retval = job.func(*job.args, **job.kwargs)
             ^^^^^^^^^^^^^^^^^^^^^^^^^^^^^^^^^
  File "C:\Users\86135\Desktop\EasyPost\backend\api\dao\https.py", line 404, in run_test_suite
    raise Exception(f"调试测试计划失败: {e}")
Exception: 调试测试计划失败: [Errno 22] Invalid argument
[2024-01-23 11:23:00,048][ThreadPoolExecutor-1_0:16664][task_id:apscheduler.executors.default][base.py:131][ERROR][Job "HttpDao.run_test_suite (trigger: cron[month='*', day='*', day_of_week='*', hour='*', minute='*'], next run at: 2024-01-23 11:24:00 CST)" raised an exception]
Traceback (most recent call last):
  File "C:\Users\86135\Desktop\EasyPost\backend\api\dao\https.py", line 401, in run_test_suite
    result = run_test(case_data)
             ^^^^^^^^^^^^^^^^^^^
  File "C:\Users\86135\Desktop\EasyPost\backend\core\engine\session_runner.py", line 44, in run_test
    suite = GenerateCase().data_to_suite(case_data)
            ^^^^^^^^^^^^^^^^^^^^^^^^^^^^^^^^^^^^^^^
  File "C:\Users\86135\Desktop\EasyPost\backend\core\engine\generate.py", line 28, in data_to_suite
    self.add_test(item, load, suite)
  File "C:\Users\86135\Desktop\EasyPost\backend\core\engine\generate.py", line 36, in add_test
    cls = self.create_test_class(item)
          ^^^^^^^^^^^^^^^^^^^^^^^^^^^^
  File "C:\Users\86135\Desktop\EasyPost\backend\core\engine\generate.py", line 50, in create_test_class
    self.create_case_content(cls, collections)
  File "C:\Users\86135\Desktop\EasyPost\backend\core\engine\generate.py", line 97, in create_case_content
    self.controller.loop(loop_count, cls, test_name, new_test_func)
  File "C:\Users\86135\Desktop\EasyPost\backend\core\engine\base.py", line 61, in loop
    self.info_log('用例第{}次循环\n'.format(c + 1))
  File "C:\Users\86135\Desktop\EasyPost\backend\core\engine\log.py", line 38, in info_log
    self.save_log(message, 'INFO')
  File "C:\Users\86135\Desktop\EasyPost\backend\core\engine\log.py", line 13, in save_log
    print(info)
OSError: [Errno 22] Invalid argument

During handling of the above exception, another exception occurred:

Traceback (most recent call last):
  File "C:\Users\86135\AppData\Local\Programs\Python\Python311\Lib\site-packages\apscheduler\executors\base.py", line 125, in run_job
    retval = job.func(*job.args, **job.kwargs)
             ^^^^^^^^^^^^^^^^^^^^^^^^^^^^^^^^^
  File "C:\Users\86135\Desktop\EasyPost\backend\api\dao\https.py", line 404, in run_test_suite
    raise Exception(f"调试测试计划失败: {e}")
Exception: 调试测试计划失败: [Errno 22] Invalid argument
[2024-01-23 11:24:00,050][ThreadPoolExecutor-1_0:16664][task_id:apscheduler.executors.default][base.py:131][ERROR][Job "HttpDao.run_test_suite (trigger: cron[month='*', day='*', day_of_week='*', hour='*', minute='*'], next run at: 2024-01-23 11:25:00 CST)" raised an exception]
Traceback (most recent call last):
  File "C:\Users\86135\Desktop\EasyPost\backend\api\dao\https.py", line 401, in run_test_suite
    result = run_test(case_data)
             ^^^^^^^^^^^^^^^^^^^
  File "C:\Users\86135\Desktop\EasyPost\backend\core\engine\session_runner.py", line 44, in run_test
    suite = GenerateCase().data_to_suite(case_data)
            ^^^^^^^^^^^^^^^^^^^^^^^^^^^^^^^^^^^^^^^
  File "C:\Users\86135\Desktop\EasyPost\backend\core\engine\generate.py", line 28, in data_to_suite
    self.add_test(item, load, suite)
  File "C:\Users\86135\Desktop\EasyPost\backend\core\engine\generate.py", line 36, in add_test
    cls = self.create_test_class(item)
          ^^^^^^^^^^^^^^^^^^^^^^^^^^^^
  File "C:\Users\86135\Desktop\EasyPost\backend\core\engine\generate.py", line 50, in create_test_class
    self.create_case_content(cls, collections)
  File "C:\Users\86135\Desktop\EasyPost\backend\core\engine\generate.py", line 97, in create_case_content
    self.controller.loop(loop_count, cls, test_name, new_test_func)
  File "C:\Users\86135\Desktop\EasyPost\backend\core\engine\base.py", line 61, in loop
    self.info_log('用例第{}次循环\n'.format(c + 1))
  File "C:\Users\86135\Desktop\EasyPost\backend\core\engine\log.py", line 38, in info_log
    self.save_log(message, 'INFO')
  File "C:\Users\86135\Desktop\EasyPost\backend\core\engine\log.py", line 13, in save_log
    print(info)
OSError: [Errno 22] Invalid argument

During handling of the above exception, another exception occurred:

Traceback (most recent call last):
  File "C:\Users\86135\AppData\Local\Programs\Python\Python311\Lib\site-packages\apscheduler\executors\base.py", line 125, in run_job
    retval = job.func(*job.args, **job.kwargs)
             ^^^^^^^^^^^^^^^^^^^^^^^^^^^^^^^^^
  File "C:\Users\86135\Desktop\EasyPost\backend\api\dao\https.py", line 404, in run_test_suite
    raise Exception(f"调试测试计划失败: {e}")
Exception: 调试测试计划失败: [Errno 22] Invalid argument
[2024-01-23 11:25:00,053][ThreadPoolExecutor-1_0:16664][task_id:apscheduler.executors.default][base.py:131][ERROR][Job "HttpDao.run_test_suite (trigger: cron[month='*', day='*', day_of_week='*', hour='*', minute='*'], next run at: 2024-01-23 11:26:00 CST)" raised an exception]
Traceback (most recent call last):
  File "C:\Users\86135\Desktop\EasyPost\backend\api\dao\https.py", line 401, in run_test_suite
    result = run_test(case_data)
             ^^^^^^^^^^^^^^^^^^^
  File "C:\Users\86135\Desktop\EasyPost\backend\core\engine\session_runner.py", line 44, in run_test
    suite = GenerateCase().data_to_suite(case_data)
            ^^^^^^^^^^^^^^^^^^^^^^^^^^^^^^^^^^^^^^^
  File "C:\Users\86135\Desktop\EasyPost\backend\core\engine\generate.py", line 28, in data_to_suite
    self.add_test(item, load, suite)
  File "C:\Users\86135\Desktop\EasyPost\backend\core\engine\generate.py", line 36, in add_test
    cls = self.create_test_class(item)
          ^^^^^^^^^^^^^^^^^^^^^^^^^^^^
  File "C:\Users\86135\Desktop\EasyPost\backend\core\engine\generate.py", line 50, in create_test_class
    self.create_case_content(cls, collections)
  File "C:\Users\86135\Desktop\EasyPost\backend\core\engine\generate.py", line 97, in create_case_content
    self.controller.loop(loop_count, cls, test_name, new_test_func)
  File "C:\Users\86135\Desktop\EasyPost\backend\core\engine\base.py", line 61, in loop
    self.info_log('用例第{}次循环\n'.format(c + 1))
  File "C:\Users\86135\Desktop\EasyPost\backend\core\engine\log.py", line 38, in info_log
    self.save_log(message, 'INFO')
  File "C:\Users\86135\Desktop\EasyPost\backend\core\engine\log.py", line 13, in save_log
    print(info)
OSError: [Errno 22] Invalid argument

During handling of the above exception, another exception occurred:

Traceback (most recent call last):
  File "C:\Users\86135\AppData\Local\Programs\Python\Python311\Lib\site-packages\apscheduler\executors\base.py", line 125, in run_job
    retval = job.func(*job.args, **job.kwargs)
             ^^^^^^^^^^^^^^^^^^^^^^^^^^^^^^^^^
  File "C:\Users\86135\Desktop\EasyPost\backend\api\dao\https.py", line 404, in run_test_suite
    raise Exception(f"调试测试计划失败: {e}")
Exception: 调试测试计划失败: [Errno 22] Invalid argument
[2024-01-23 11:26:00,053][ThreadPoolExecutor-1_0:16664][task_id:apscheduler.executors.default][base.py:131][ERROR][Job "HttpDao.run_test_suite (trigger: cron[month='*', day='*', day_of_week='*', hour='*', minute='*'], next run at: 2024-01-23 11:27:00 CST)" raised an exception]
Traceback (most recent call last):
  File "C:\Users\86135\Desktop\EasyPost\backend\api\dao\https.py", line 401, in run_test_suite
    result = run_test(case_data)
             ^^^^^^^^^^^^^^^^^^^
  File "C:\Users\86135\Desktop\EasyPost\backend\core\engine\session_runner.py", line 44, in run_test
    suite = GenerateCase().data_to_suite(case_data)
            ^^^^^^^^^^^^^^^^^^^^^^^^^^^^^^^^^^^^^^^
  File "C:\Users\86135\Desktop\EasyPost\backend\core\engine\generate.py", line 28, in data_to_suite
    self.add_test(item, load, suite)
  File "C:\Users\86135\Desktop\EasyPost\backend\core\engine\generate.py", line 36, in add_test
    cls = self.create_test_class(item)
          ^^^^^^^^^^^^^^^^^^^^^^^^^^^^
  File "C:\Users\86135\Desktop\EasyPost\backend\core\engine\generate.py", line 50, in create_test_class
    self.create_case_content(cls, collections)
  File "C:\Users\86135\Desktop\EasyPost\backend\core\engine\generate.py", line 97, in create_case_content
    self.controller.loop(loop_count, cls, test_name, new_test_func)
  File "C:\Users\86135\Desktop\EasyPost\backend\core\engine\base.py", line 61, in loop
    self.info_log('用例第{}次循环\n'.format(c + 1))
  File "C:\Users\86135\Desktop\EasyPost\backend\core\engine\log.py", line 38, in info_log
    self.save_log(message, 'INFO')
  File "C:\Users\86135\Desktop\EasyPost\backend\core\engine\log.py", line 13, in save_log
    print(info)
OSError: [Errno 22] Invalid argument

During handling of the above exception, another exception occurred:

Traceback (most recent call last):
  File "C:\Users\86135\AppData\Local\Programs\Python\Python311\Lib\site-packages\apscheduler\executors\base.py", line 125, in run_job
    retval = job.func(*job.args, **job.kwargs)
             ^^^^^^^^^^^^^^^^^^^^^^^^^^^^^^^^^
  File "C:\Users\86135\Desktop\EasyPost\backend\api\dao\https.py", line 404, in run_test_suite
    raise Exception(f"调试测试计划失败: {e}")
Exception: 调试测试计划失败: [Errno 22] Invalid argument
[2024-01-23 11:27:00,050][ThreadPoolExecutor-1_0:16664][task_id:apscheduler.executors.default][base.py:131][ERROR][Job "HttpDao.run_test_suite (trigger: cron[month='*', day='*', day_of_week='*', hour='*', minute='*'], next run at: 2024-01-23 11:28:00 CST)" raised an exception]
Traceback (most recent call last):
  File "C:\Users\86135\Desktop\EasyPost\backend\api\dao\https.py", line 401, in run_test_suite
    result = run_test(case_data)
             ^^^^^^^^^^^^^^^^^^^
  File "C:\Users\86135\Desktop\EasyPost\backend\core\engine\session_runner.py", line 44, in run_test
    suite = GenerateCase().data_to_suite(case_data)
            ^^^^^^^^^^^^^^^^^^^^^^^^^^^^^^^^^^^^^^^
  File "C:\Users\86135\Desktop\EasyPost\backend\core\engine\generate.py", line 28, in data_to_suite
    self.add_test(item, load, suite)
  File "C:\Users\86135\Desktop\EasyPost\backend\core\engine\generate.py", line 36, in add_test
    cls = self.create_test_class(item)
          ^^^^^^^^^^^^^^^^^^^^^^^^^^^^
  File "C:\Users\86135\Desktop\EasyPost\backend\core\engine\generate.py", line 50, in create_test_class
    self.create_case_content(cls, collections)
  File "C:\Users\86135\Desktop\EasyPost\backend\core\engine\generate.py", line 97, in create_case_content
    self.controller.loop(loop_count, cls, test_name, new_test_func)
  File "C:\Users\86135\Desktop\EasyPost\backend\core\engine\base.py", line 61, in loop
    self.info_log('用例第{}次循环\n'.format(c + 1))
  File "C:\Users\86135\Desktop\EasyPost\backend\core\engine\log.py", line 38, in info_log
    self.save_log(message, 'INFO')
  File "C:\Users\86135\Desktop\EasyPost\backend\core\engine\log.py", line 13, in save_log
    print(info)
OSError: [Errno 22] Invalid argument

During handling of the above exception, another exception occurred:

Traceback (most recent call last):
  File "C:\Users\86135\AppData\Local\Programs\Python\Python311\Lib\site-packages\apscheduler\executors\base.py", line 125, in run_job
    retval = job.func(*job.args, **job.kwargs)
             ^^^^^^^^^^^^^^^^^^^^^^^^^^^^^^^^^
  File "C:\Users\86135\Desktop\EasyPost\backend\api\dao\https.py", line 404, in run_test_suite
    raise Exception(f"调试测试计划失败: {e}")
Exception: 调试测试计划失败: [Errno 22] Invalid argument
[2024-01-23 11:28:00,055][ThreadPoolExecutor-1_0:16664][task_id:apscheduler.executors.default][base.py:131][ERROR][Job "HttpDao.run_test_suite (trigger: cron[month='*', day='*', day_of_week='*', hour='*', minute='*'], next run at: 2024-01-23 11:29:00 CST)" raised an exception]
Traceback (most recent call last):
  File "C:\Users\86135\Desktop\EasyPost\backend\api\dao\https.py", line 401, in run_test_suite
    result = run_test(case_data)
             ^^^^^^^^^^^^^^^^^^^
  File "C:\Users\86135\Desktop\EasyPost\backend\core\engine\session_runner.py", line 44, in run_test
    suite = GenerateCase().data_to_suite(case_data)
            ^^^^^^^^^^^^^^^^^^^^^^^^^^^^^^^^^^^^^^^
  File "C:\Users\86135\Desktop\EasyPost\backend\core\engine\generate.py", line 28, in data_to_suite
    self.add_test(item, load, suite)
  File "C:\Users\86135\Desktop\EasyPost\backend\core\engine\generate.py", line 36, in add_test
    cls = self.create_test_class(item)
          ^^^^^^^^^^^^^^^^^^^^^^^^^^^^
  File "C:\Users\86135\Desktop\EasyPost\backend\core\engine\generate.py", line 50, in create_test_class
    self.create_case_content(cls, collections)
  File "C:\Users\86135\Desktop\EasyPost\backend\core\engine\generate.py", line 97, in create_case_content
    self.controller.loop(loop_count, cls, test_name, new_test_func)
  File "C:\Users\86135\Desktop\EasyPost\backend\core\engine\base.py", line 61, in loop
    self.info_log('用例第{}次循环\n'.format(c + 1))
  File "C:\Users\86135\Desktop\EasyPost\backend\core\engine\log.py", line 38, in info_log
    self.save_log(message, 'INFO')
  File "C:\Users\86135\Desktop\EasyPost\backend\core\engine\log.py", line 13, in save_log
    print(info)
OSError: [Errno 22] Invalid argument

During handling of the above exception, another exception occurred:

Traceback (most recent call last):
  File "C:\Users\86135\AppData\Local\Programs\Python\Python311\Lib\site-packages\apscheduler\executors\base.py", line 125, in run_job
    retval = job.func(*job.args, **job.kwargs)
             ^^^^^^^^^^^^^^^^^^^^^^^^^^^^^^^^^
  File "C:\Users\86135\Desktop\EasyPost\backend\api\dao\https.py", line 404, in run_test_suite
    raise Exception(f"调试测试计划失败: {e}")
Exception: 调试测试计划失败: [Errno 22] Invalid argument
[2024-01-23 11:29:00,056][ThreadPoolExecutor-1_0:16664][task_id:apscheduler.executors.default][base.py:131][ERROR][Job "HttpDao.run_test_suite (trigger: cron[month='*', day='*', day_of_week='*', hour='*', minute='*'], next run at: 2024-01-23 11:30:00 CST)" raised an exception]
Traceback (most recent call last):
  File "C:\Users\86135\Desktop\EasyPost\backend\api\dao\https.py", line 401, in run_test_suite
    result = run_test(case_data)
             ^^^^^^^^^^^^^^^^^^^
  File "C:\Users\86135\Desktop\EasyPost\backend\core\engine\session_runner.py", line 44, in run_test
    suite = GenerateCase().data_to_suite(case_data)
            ^^^^^^^^^^^^^^^^^^^^^^^^^^^^^^^^^^^^^^^
  File "C:\Users\86135\Desktop\EasyPost\backend\core\engine\generate.py", line 28, in data_to_suite
    self.add_test(item, load, suite)
  File "C:\Users\86135\Desktop\EasyPost\backend\core\engine\generate.py", line 36, in add_test
    cls = self.create_test_class(item)
          ^^^^^^^^^^^^^^^^^^^^^^^^^^^^
  File "C:\Users\86135\Desktop\EasyPost\backend\core\engine\generate.py", line 50, in create_test_class
    self.create_case_content(cls, collections)
  File "C:\Users\86135\Desktop\EasyPost\backend\core\engine\generate.py", line 97, in create_case_content
    self.controller.loop(loop_count, cls, test_name, new_test_func)
  File "C:\Users\86135\Desktop\EasyPost\backend\core\engine\base.py", line 61, in loop
    self.info_log('用例第{}次循环\n'.format(c + 1))
  File "C:\Users\86135\Desktop\EasyPost\backend\core\engine\log.py", line 38, in info_log
    self.save_log(message, 'INFO')
  File "C:\Users\86135\Desktop\EasyPost\backend\core\engine\log.py", line 13, in save_log
    print(info)
OSError: [Errno 22] Invalid argument

During handling of the above exception, another exception occurred:

Traceback (most recent call last):
  File "C:\Users\86135\AppData\Local\Programs\Python\Python311\Lib\site-packages\apscheduler\executors\base.py", line 125, in run_job
    retval = job.func(*job.args, **job.kwargs)
             ^^^^^^^^^^^^^^^^^^^^^^^^^^^^^^^^^
  File "C:\Users\86135\Desktop\EasyPost\backend\api\dao\https.py", line 404, in run_test_suite
    raise Exception(f"调试测试计划失败: {e}")
Exception: 调试测试计划失败: [Errno 22] Invalid argument
[2024-01-23 11:30:00,041][ThreadPoolExecutor-1_0:16664][task_id:apscheduler.executors.default][base.py:131][ERROR][Job "HttpDao.run_test_suite (trigger: cron[month='*', day='*', day_of_week='*', hour='*', minute='*'], next run at: 2024-01-23 11:31:00 CST)" raised an exception]
Traceback (most recent call last):
  File "C:\Users\86135\Desktop\EasyPost\backend\api\dao\https.py", line 401, in run_test_suite
    result = run_test(case_data)
             ^^^^^^^^^^^^^^^^^^^
  File "C:\Users\86135\Desktop\EasyPost\backend\core\engine\session_runner.py", line 44, in run_test
    suite = GenerateCase().data_to_suite(case_data)
            ^^^^^^^^^^^^^^^^^^^^^^^^^^^^^^^^^^^^^^^
  File "C:\Users\86135\Desktop\EasyPost\backend\core\engine\generate.py", line 28, in data_to_suite
    self.add_test(item, load, suite)
  File "C:\Users\86135\Desktop\EasyPost\backend\core\engine\generate.py", line 36, in add_test
    cls = self.create_test_class(item)
          ^^^^^^^^^^^^^^^^^^^^^^^^^^^^
  File "C:\Users\86135\Desktop\EasyPost\backend\core\engine\generate.py", line 50, in create_test_class
    self.create_case_content(cls, collections)
  File "C:\Users\86135\Desktop\EasyPost\backend\core\engine\generate.py", line 97, in create_case_content
    self.controller.loop(loop_count, cls, test_name, new_test_func)
  File "C:\Users\86135\Desktop\EasyPost\backend\core\engine\base.py", line 61, in loop
    self.info_log('用例第{}次循环\n'.format(c + 1))
  File "C:\Users\86135\Desktop\EasyPost\backend\core\engine\log.py", line 38, in info_log
    self.save_log(message, 'INFO')
  File "C:\Users\86135\Desktop\EasyPost\backend\core\engine\log.py", line 13, in save_log
    print(info)
OSError: [Errno 22] Invalid argument

During handling of the above exception, another exception occurred:

Traceback (most recent call last):
  File "C:\Users\86135\AppData\Local\Programs\Python\Python311\Lib\site-packages\apscheduler\executors\base.py", line 125, in run_job
    retval = job.func(*job.args, **job.kwargs)
             ^^^^^^^^^^^^^^^^^^^^^^^^^^^^^^^^^
  File "C:\Users\86135\Desktop\EasyPost\backend\api\dao\https.py", line 404, in run_test_suite
    raise Exception(f"调试测试计划失败: {e}")
Exception: 调试测试计划失败: [Errno 22] Invalid argument
[2024-01-23 11:31:00,061][ThreadPoolExecutor-1_0:16664][task_id:apscheduler.executors.default][base.py:131][ERROR][Job "HttpDao.run_test_suite (trigger: cron[month='*', day='*', day_of_week='*', hour='*', minute='*'], next run at: 2024-01-23 11:32:00 CST)" raised an exception]
Traceback (most recent call last):
  File "C:\Users\86135\Desktop\EasyPost\backend\api\dao\https.py", line 401, in run_test_suite
    result = run_test(case_data)
             ^^^^^^^^^^^^^^^^^^^
  File "C:\Users\86135\Desktop\EasyPost\backend\core\engine\session_runner.py", line 44, in run_test
    suite = GenerateCase().data_to_suite(case_data)
            ^^^^^^^^^^^^^^^^^^^^^^^^^^^^^^^^^^^^^^^
  File "C:\Users\86135\Desktop\EasyPost\backend\core\engine\generate.py", line 28, in data_to_suite
    self.add_test(item, load, suite)
  File "C:\Users\86135\Desktop\EasyPost\backend\core\engine\generate.py", line 36, in add_test
    cls = self.create_test_class(item)
          ^^^^^^^^^^^^^^^^^^^^^^^^^^^^
  File "C:\Users\86135\Desktop\EasyPost\backend\core\engine\generate.py", line 50, in create_test_class
    self.create_case_content(cls, collections)
  File "C:\Users\86135\Desktop\EasyPost\backend\core\engine\generate.py", line 97, in create_case_content
    self.controller.loop(loop_count, cls, test_name, new_test_func)
  File "C:\Users\86135\Desktop\EasyPost\backend\core\engine\base.py", line 61, in loop
    self.info_log('用例第{}次循环\n'.format(c + 1))
  File "C:\Users\86135\Desktop\EasyPost\backend\core\engine\log.py", line 38, in info_log
    self.save_log(message, 'INFO')
  File "C:\Users\86135\Desktop\EasyPost\backend\core\engine\log.py", line 13, in save_log
    print(info)
OSError: [Errno 22] Invalid argument

During handling of the above exception, another exception occurred:

Traceback (most recent call last):
  File "C:\Users\86135\AppData\Local\Programs\Python\Python311\Lib\site-packages\apscheduler\executors\base.py", line 125, in run_job
    retval = job.func(*job.args, **job.kwargs)
             ^^^^^^^^^^^^^^^^^^^^^^^^^^^^^^^^^
  File "C:\Users\86135\Desktop\EasyPost\backend\api\dao\https.py", line 404, in run_test_suite
    raise Exception(f"调试测试计划失败: {e}")
Exception: 调试测试计划失败: [Errno 22] Invalid argument
[2024-01-23 11:32:00,046][ThreadPoolExecutor-1_0:16664][task_id:apscheduler.executors.default][base.py:131][ERROR][Job "HttpDao.run_test_suite (trigger: cron[month='*', day='*', day_of_week='*', hour='*', minute='*'], next run at: 2024-01-23 11:33:00 CST)" raised an exception]
Traceback (most recent call last):
  File "C:\Users\86135\Desktop\EasyPost\backend\api\dao\https.py", line 401, in run_test_suite
    result = run_test(case_data)
             ^^^^^^^^^^^^^^^^^^^
  File "C:\Users\86135\Desktop\EasyPost\backend\core\engine\session_runner.py", line 44, in run_test
    suite = GenerateCase().data_to_suite(case_data)
            ^^^^^^^^^^^^^^^^^^^^^^^^^^^^^^^^^^^^^^^
  File "C:\Users\86135\Desktop\EasyPost\backend\core\engine\generate.py", line 28, in data_to_suite
    self.add_test(item, load, suite)
  File "C:\Users\86135\Desktop\EasyPost\backend\core\engine\generate.py", line 36, in add_test
    cls = self.create_test_class(item)
          ^^^^^^^^^^^^^^^^^^^^^^^^^^^^
  File "C:\Users\86135\Desktop\EasyPost\backend\core\engine\generate.py", line 50, in create_test_class
    self.create_case_content(cls, collections)
  File "C:\Users\86135\Desktop\EasyPost\backend\core\engine\generate.py", line 97, in create_case_content
    self.controller.loop(loop_count, cls, test_name, new_test_func)
  File "C:\Users\86135\Desktop\EasyPost\backend\core\engine\base.py", line 61, in loop
    self.info_log('用例第{}次循环\n'.format(c + 1))
  File "C:\Users\86135\Desktop\EasyPost\backend\core\engine\log.py", line 38, in info_log
    self.save_log(message, 'INFO')
  File "C:\Users\86135\Desktop\EasyPost\backend\core\engine\log.py", line 13, in save_log
    print(info)
OSError: [Errno 22] Invalid argument

During handling of the above exception, another exception occurred:

Traceback (most recent call last):
  File "C:\Users\86135\AppData\Local\Programs\Python\Python311\Lib\site-packages\apscheduler\executors\base.py", line 125, in run_job
    retval = job.func(*job.args, **job.kwargs)
             ^^^^^^^^^^^^^^^^^^^^^^^^^^^^^^^^^
  File "C:\Users\86135\Desktop\EasyPost\backend\api\dao\https.py", line 404, in run_test_suite
    raise Exception(f"调试测试计划失败: {e}")
Exception: 调试测试计划失败: [Errno 22] Invalid argument
[2024-01-23 11:33:00,045][ThreadPoolExecutor-1_0:16664][task_id:apscheduler.executors.default][base.py:131][ERROR][Job "HttpDao.run_test_suite (trigger: cron[month='*', day='*', day_of_week='*', hour='*', minute='*'], next run at: 2024-01-23 11:34:00 CST)" raised an exception]
Traceback (most recent call last):
  File "C:\Users\86135\Desktop\EasyPost\backend\api\dao\https.py", line 401, in run_test_suite
    result = run_test(case_data)
             ^^^^^^^^^^^^^^^^^^^
  File "C:\Users\86135\Desktop\EasyPost\backend\core\engine\session_runner.py", line 44, in run_test
    suite = GenerateCase().data_to_suite(case_data)
            ^^^^^^^^^^^^^^^^^^^^^^^^^^^^^^^^^^^^^^^
  File "C:\Users\86135\Desktop\EasyPost\backend\core\engine\generate.py", line 28, in data_to_suite
    self.add_test(item, load, suite)
  File "C:\Users\86135\Desktop\EasyPost\backend\core\engine\generate.py", line 36, in add_test
    cls = self.create_test_class(item)
          ^^^^^^^^^^^^^^^^^^^^^^^^^^^^
  File "C:\Users\86135\Desktop\EasyPost\backend\core\engine\generate.py", line 50, in create_test_class
    self.create_case_content(cls, collections)
  File "C:\Users\86135\Desktop\EasyPost\backend\core\engine\generate.py", line 97, in create_case_content
    self.controller.loop(loop_count, cls, test_name, new_test_func)
  File "C:\Users\86135\Desktop\EasyPost\backend\core\engine\base.py", line 61, in loop
    self.info_log('用例第{}次循环\n'.format(c + 1))
  File "C:\Users\86135\Desktop\EasyPost\backend\core\engine\log.py", line 38, in info_log
    self.save_log(message, 'INFO')
  File "C:\Users\86135\Desktop\EasyPost\backend\core\engine\log.py", line 13, in save_log
    print(info)
OSError: [Errno 22] Invalid argument

During handling of the above exception, another exception occurred:

Traceback (most recent call last):
  File "C:\Users\86135\AppData\Local\Programs\Python\Python311\Lib\site-packages\apscheduler\executors\base.py", line 125, in run_job
    retval = job.func(*job.args, **job.kwargs)
             ^^^^^^^^^^^^^^^^^^^^^^^^^^^^^^^^^
  File "C:\Users\86135\Desktop\EasyPost\backend\api\dao\https.py", line 404, in run_test_suite
    raise Exception(f"调试测试计划失败: {e}")
Exception: 调试测试计划失败: [Errno 22] Invalid argument
[2024-01-23 11:34:00,053][ThreadPoolExecutor-1_0:16664][task_id:apscheduler.executors.default][base.py:131][ERROR][Job "HttpDao.run_test_suite (trigger: cron[month='*', day='*', day_of_week='*', hour='*', minute='*'], next run at: 2024-01-23 11:35:00 CST)" raised an exception]
Traceback (most recent call last):
  File "C:\Users\86135\Desktop\EasyPost\backend\api\dao\https.py", line 401, in run_test_suite
    result = run_test(case_data)
             ^^^^^^^^^^^^^^^^^^^
  File "C:\Users\86135\Desktop\EasyPost\backend\core\engine\session_runner.py", line 44, in run_test
    suite = GenerateCase().data_to_suite(case_data)
            ^^^^^^^^^^^^^^^^^^^^^^^^^^^^^^^^^^^^^^^
  File "C:\Users\86135\Desktop\EasyPost\backend\core\engine\generate.py", line 28, in data_to_suite
    self.add_test(item, load, suite)
  File "C:\Users\86135\Desktop\EasyPost\backend\core\engine\generate.py", line 36, in add_test
    cls = self.create_test_class(item)
          ^^^^^^^^^^^^^^^^^^^^^^^^^^^^
  File "C:\Users\86135\Desktop\EasyPost\backend\core\engine\generate.py", line 50, in create_test_class
    self.create_case_content(cls, collections)
  File "C:\Users\86135\Desktop\EasyPost\backend\core\engine\generate.py", line 97, in create_case_content
    self.controller.loop(loop_count, cls, test_name, new_test_func)
  File "C:\Users\86135\Desktop\EasyPost\backend\core\engine\base.py", line 61, in loop
    self.info_log('用例第{}次循环\n'.format(c + 1))
  File "C:\Users\86135\Desktop\EasyPost\backend\core\engine\log.py", line 38, in info_log
    self.save_log(message, 'INFO')
  File "C:\Users\86135\Desktop\EasyPost\backend\core\engine\log.py", line 13, in save_log
    print(info)
OSError: [Errno 22] Invalid argument

During handling of the above exception, another exception occurred:

Traceback (most recent call last):
  File "C:\Users\86135\AppData\Local\Programs\Python\Python311\Lib\site-packages\apscheduler\executors\base.py", line 125, in run_job
    retval = job.func(*job.args, **job.kwargs)
             ^^^^^^^^^^^^^^^^^^^^^^^^^^^^^^^^^
  File "C:\Users\86135\Desktop\EasyPost\backend\api\dao\https.py", line 404, in run_test_suite
    raise Exception(f"调试测试计划失败: {e}")
Exception: 调试测试计划失败: [Errno 22] Invalid argument
[2024-01-23 11:35:00,051][ThreadPoolExecutor-1_0:16664][task_id:apscheduler.executors.default][base.py:131][ERROR][Job "HttpDao.run_test_suite (trigger: cron[month='*', day='*', day_of_week='*', hour='*', minute='*'], next run at: 2024-01-23 11:36:00 CST)" raised an exception]
Traceback (most recent call last):
  File "C:\Users\86135\Desktop\EasyPost\backend\api\dao\https.py", line 401, in run_test_suite
    result = run_test(case_data)
             ^^^^^^^^^^^^^^^^^^^
  File "C:\Users\86135\Desktop\EasyPost\backend\core\engine\session_runner.py", line 44, in run_test
    suite = GenerateCase().data_to_suite(case_data)
            ^^^^^^^^^^^^^^^^^^^^^^^^^^^^^^^^^^^^^^^
  File "C:\Users\86135\Desktop\EasyPost\backend\core\engine\generate.py", line 28, in data_to_suite
    self.add_test(item, load, suite)
  File "C:\Users\86135\Desktop\EasyPost\backend\core\engine\generate.py", line 36, in add_test
    cls = self.create_test_class(item)
          ^^^^^^^^^^^^^^^^^^^^^^^^^^^^
  File "C:\Users\86135\Desktop\EasyPost\backend\core\engine\generate.py", line 50, in create_test_class
    self.create_case_content(cls, collections)
  File "C:\Users\86135\Desktop\EasyPost\backend\core\engine\generate.py", line 97, in create_case_content
    self.controller.loop(loop_count, cls, test_name, new_test_func)
  File "C:\Users\86135\Desktop\EasyPost\backend\core\engine\base.py", line 61, in loop
    self.info_log('用例第{}次循环\n'.format(c + 1))
  File "C:\Users\86135\Desktop\EasyPost\backend\core\engine\log.py", line 38, in info_log
    self.save_log(message, 'INFO')
  File "C:\Users\86135\Desktop\EasyPost\backend\core\engine\log.py", line 13, in save_log
    print(info)
OSError: [Errno 22] Invalid argument

During handling of the above exception, another exception occurred:

Traceback (most recent call last):
  File "C:\Users\86135\AppData\Local\Programs\Python\Python311\Lib\site-packages\apscheduler\executors\base.py", line 125, in run_job
    retval = job.func(*job.args, **job.kwargs)
             ^^^^^^^^^^^^^^^^^^^^^^^^^^^^^^^^^
  File "C:\Users\86135\Desktop\EasyPost\backend\api\dao\https.py", line 404, in run_test_suite
    raise Exception(f"调试测试计划失败: {e}")
Exception: 调试测试计划失败: [Errno 22] Invalid argument
[2024-01-23 11:36:00,044][ThreadPoolExecutor-1_0:16664][task_id:apscheduler.executors.default][base.py:131][ERROR][Job "HttpDao.run_test_suite (trigger: cron[month='*', day='*', day_of_week='*', hour='*', minute='*'], next run at: 2024-01-23 11:37:00 CST)" raised an exception]
Traceback (most recent call last):
  File "C:\Users\86135\Desktop\EasyPost\backend\api\dao\https.py", line 401, in run_test_suite
    result = run_test(case_data)
             ^^^^^^^^^^^^^^^^^^^
  File "C:\Users\86135\Desktop\EasyPost\backend\core\engine\session_runner.py", line 44, in run_test
    suite = GenerateCase().data_to_suite(case_data)
            ^^^^^^^^^^^^^^^^^^^^^^^^^^^^^^^^^^^^^^^
  File "C:\Users\86135\Desktop\EasyPost\backend\core\engine\generate.py", line 28, in data_to_suite
    self.add_test(item, load, suite)
  File "C:\Users\86135\Desktop\EasyPost\backend\core\engine\generate.py", line 36, in add_test
    cls = self.create_test_class(item)
          ^^^^^^^^^^^^^^^^^^^^^^^^^^^^
  File "C:\Users\86135\Desktop\EasyPost\backend\core\engine\generate.py", line 50, in create_test_class
    self.create_case_content(cls, collections)
  File "C:\Users\86135\Desktop\EasyPost\backend\core\engine\generate.py", line 97, in create_case_content
    self.controller.loop(loop_count, cls, test_name, new_test_func)
  File "C:\Users\86135\Desktop\EasyPost\backend\core\engine\base.py", line 61, in loop
    self.info_log('用例第{}次循环\n'.format(c + 1))
  File "C:\Users\86135\Desktop\EasyPost\backend\core\engine\log.py", line 38, in info_log
    self.save_log(message, 'INFO')
  File "C:\Users\86135\Desktop\EasyPost\backend\core\engine\log.py", line 13, in save_log
    print(info)
OSError: [Errno 22] Invalid argument

During handling of the above exception, another exception occurred:

Traceback (most recent call last):
  File "C:\Users\86135\AppData\Local\Programs\Python\Python311\Lib\site-packages\apscheduler\executors\base.py", line 125, in run_job
    retval = job.func(*job.args, **job.kwargs)
             ^^^^^^^^^^^^^^^^^^^^^^^^^^^^^^^^^
  File "C:\Users\86135\Desktop\EasyPost\backend\api\dao\https.py", line 404, in run_test_suite
    raise Exception(f"调试测试计划失败: {e}")
Exception: 调试测试计划失败: [Errno 22] Invalid argument
[2024-01-23 11:37:00,055][ThreadPoolExecutor-1_0:16664][task_id:apscheduler.executors.default][base.py:131][ERROR][Job "HttpDao.run_test_suite (trigger: cron[month='*', day='*', day_of_week='*', hour='*', minute='*'], next run at: 2024-01-23 11:38:00 CST)" raised an exception]
Traceback (most recent call last):
  File "C:\Users\86135\Desktop\EasyPost\backend\api\dao\https.py", line 401, in run_test_suite
    result = run_test(case_data)
             ^^^^^^^^^^^^^^^^^^^
  File "C:\Users\86135\Desktop\EasyPost\backend\core\engine\session_runner.py", line 44, in run_test
    suite = GenerateCase().data_to_suite(case_data)
            ^^^^^^^^^^^^^^^^^^^^^^^^^^^^^^^^^^^^^^^
  File "C:\Users\86135\Desktop\EasyPost\backend\core\engine\generate.py", line 28, in data_to_suite
    self.add_test(item, load, suite)
  File "C:\Users\86135\Desktop\EasyPost\backend\core\engine\generate.py", line 36, in add_test
    cls = self.create_test_class(item)
          ^^^^^^^^^^^^^^^^^^^^^^^^^^^^
  File "C:\Users\86135\Desktop\EasyPost\backend\core\engine\generate.py", line 50, in create_test_class
    self.create_case_content(cls, collections)
  File "C:\Users\86135\Desktop\EasyPost\backend\core\engine\generate.py", line 97, in create_case_content
    self.controller.loop(loop_count, cls, test_name, new_test_func)
  File "C:\Users\86135\Desktop\EasyPost\backend\core\engine\base.py", line 61, in loop
    self.info_log('用例第{}次循环\n'.format(c + 1))
  File "C:\Users\86135\Desktop\EasyPost\backend\core\engine\log.py", line 38, in info_log
    self.save_log(message, 'INFO')
  File "C:\Users\86135\Desktop\EasyPost\backend\core\engine\log.py", line 13, in save_log
    print(info)
OSError: [Errno 22] Invalid argument

During handling of the above exception, another exception occurred:

Traceback (most recent call last):
  File "C:\Users\86135\AppData\Local\Programs\Python\Python311\Lib\site-packages\apscheduler\executors\base.py", line 125, in run_job
    retval = job.func(*job.args, **job.kwargs)
             ^^^^^^^^^^^^^^^^^^^^^^^^^^^^^^^^^
  File "C:\Users\86135\Desktop\EasyPost\backend\api\dao\https.py", line 404, in run_test_suite
    raise Exception(f"调试测试计划失败: {e}")
Exception: 调试测试计划失败: [Errno 22] Invalid argument
[2024-01-23 11:38:00,052][ThreadPoolExecutor-1_0:16664][task_id:apscheduler.executors.default][base.py:131][ERROR][Job "HttpDao.run_test_suite (trigger: cron[month='*', day='*', day_of_week='*', hour='*', minute='*'], next run at: 2024-01-23 11:39:00 CST)" raised an exception]
Traceback (most recent call last):
  File "C:\Users\86135\Desktop\EasyPost\backend\api\dao\https.py", line 401, in run_test_suite
    result = run_test(case_data)
             ^^^^^^^^^^^^^^^^^^^
  File "C:\Users\86135\Desktop\EasyPost\backend\core\engine\session_runner.py", line 44, in run_test
    suite = GenerateCase().data_to_suite(case_data)
            ^^^^^^^^^^^^^^^^^^^^^^^^^^^^^^^^^^^^^^^
  File "C:\Users\86135\Desktop\EasyPost\backend\core\engine\generate.py", line 28, in data_to_suite
    self.add_test(item, load, suite)
  File "C:\Users\86135\Desktop\EasyPost\backend\core\engine\generate.py", line 36, in add_test
    cls = self.create_test_class(item)
          ^^^^^^^^^^^^^^^^^^^^^^^^^^^^
  File "C:\Users\86135\Desktop\EasyPost\backend\core\engine\generate.py", line 50, in create_test_class
    self.create_case_content(cls, collections)
  File "C:\Users\86135\Desktop\EasyPost\backend\core\engine\generate.py", line 97, in create_case_content
    self.controller.loop(loop_count, cls, test_name, new_test_func)
  File "C:\Users\86135\Desktop\EasyPost\backend\core\engine\base.py", line 61, in loop
    self.info_log('用例第{}次循环\n'.format(c + 1))
  File "C:\Users\86135\Desktop\EasyPost\backend\core\engine\log.py", line 38, in info_log
    self.save_log(message, 'INFO')
  File "C:\Users\86135\Desktop\EasyPost\backend\core\engine\log.py", line 13, in save_log
    print(info)
OSError: [Errno 22] Invalid argument

During handling of the above exception, another exception occurred:

Traceback (most recent call last):
  File "C:\Users\86135\AppData\Local\Programs\Python\Python311\Lib\site-packages\apscheduler\executors\base.py", line 125, in run_job
    retval = job.func(*job.args, **job.kwargs)
             ^^^^^^^^^^^^^^^^^^^^^^^^^^^^^^^^^
  File "C:\Users\86135\Desktop\EasyPost\backend\api\dao\https.py", line 404, in run_test_suite
    raise Exception(f"调试测试计划失败: {e}")
Exception: 调试测试计划失败: [Errno 22] Invalid argument
[2024-01-25 15:34:29,436][Thread-3 (process_request_thread):27500][task_id:celery.backends.redis][redis.py:391][ERROR][Connection to Redis lost: Retry (0/20) now.]
[2024-01-25 15:34:29,437][Thread-3 (process_request_thread):27500][task_id:celery.backends.redis][redis.py:391][ERROR][Connection to Redis lost: Retry (1/20) in 1.00 second.]
[2024-01-25 15:34:30,439][Thread-3 (process_request_thread):27500][task_id:celery.backends.redis][redis.py:391][ERROR][Connection to Redis lost: Retry (2/20) in 1.00 second.]
[2024-01-25 15:34:31,440][Thread-3 (process_request_thread):27500][task_id:celery.backends.redis][redis.py:391][ERROR][Connection to Redis lost: Retry (3/20) in 1.00 second.]
[2024-01-25 15:34:32,441][Thread-3 (process_request_thread):27500][task_id:celery.backends.redis][redis.py:391][ERROR][Connection to Redis lost: Retry (4/20) in 1.00 second.]
[2024-01-25 15:34:33,443][Thread-3 (process_request_thread):27500][task_id:celery.backends.redis][redis.py:391][ERROR][Connection to Redis lost: Retry (5/20) in 1.00 second.]
[2024-01-25 15:34:34,466][Thread-3 (process_request_thread):27500][task_id:celery.backends.redis][redis.py:391][ERROR][Connection to Redis lost: Retry (6/20) in 1.00 second.]
[2024-01-25 15:34:35,469][Thread-3 (process_request_thread):27500][task_id:celery.backends.redis][redis.py:391][ERROR][Connection to Redis lost: Retry (7/20) in 1.00 second.]
[2024-01-25 15:34:36,486][Thread-3 (process_request_thread):27500][task_id:celery.backends.redis][redis.py:391][ERROR][Connection to Redis lost: Retry (8/20) in 1.00 second.]
[2024-01-25 15:34:37,512][Thread-3 (process_request_thread):27500][task_id:celery.backends.redis][redis.py:391][ERROR][Connection to Redis lost: Retry (9/20) in 1.00 second.]
[2024-01-25 15:34:38,529][Thread-3 (process_request_thread):27500][task_id:celery.backends.redis][redis.py:391][ERROR][Connection to Redis lost: Retry (10/20) in 1.00 second.]
[2024-01-25 15:34:39,531][Thread-3 (process_request_thread):27500][task_id:celery.backends.redis][redis.py:391][ERROR][Connection to Redis lost: Retry (11/20) in 1.00 second.]
[2024-01-25 15:34:40,533][Thread-3 (process_request_thread):27500][task_id:celery.backends.redis][redis.py:391][ERROR][Connection to Redis lost: Retry (12/20) in 1.00 second.]
[2024-01-25 15:34:41,535][Thread-3 (process_request_thread):27500][task_id:celery.backends.redis][redis.py:391][ERROR][Connection to Redis lost: Retry (13/20) in 1.00 second.]
[2024-01-25 15:34:42,537][Thread-3 (process_request_thread):27500][task_id:celery.backends.redis][redis.py:391][ERROR][Connection to Redis lost: Retry (14/20) in 1.00 second.]
[2024-01-25 15:34:43,542][Thread-3 (process_request_thread):27500][task_id:celery.backends.redis][redis.py:391][ERROR][Connection to Redis lost: Retry (15/20) in 1.00 second.]
[2024-01-25 15:34:44,544][Thread-3 (process_request_thread):27500][task_id:celery.backends.redis][redis.py:391][ERROR][Connection to Redis lost: Retry (16/20) in 1.00 second.]
[2024-01-25 15:34:45,545][Thread-3 (process_request_thread):27500][task_id:celery.backends.redis][redis.py:391][ERROR][Connection to Redis lost: Retry (17/20) in 1.00 second.]
[2024-01-25 15:34:46,546][Thread-3 (process_request_thread):27500][task_id:celery.backends.redis][redis.py:391][ERROR][Connection to Redis lost: Retry (18/20) in 1.00 second.]
[2024-01-25 15:34:47,548][Thread-3 (process_request_thread):27500][task_id:celery.backends.redis][redis.py:391][ERROR][Connection to Redis lost: Retry (19/20) in 1.00 second.]
[2024-01-25 15:34:48,563][Thread-3 (process_request_thread):27500][task_id:celery.backends.redis][redis.py:132][CRITICAL][
Retry limit exceeded while trying to reconnect to the Celery redis result store backend. The Celery application must be restarted.
]
[2024-01-26 13:29:50,375][Thread-4 (process_request_thread):27848][task_id:django.request][log.py:241][ERROR][Internal Server Error: /api/tree/178]
Traceback (most recent call last):
  File "C:\Users\86135\AppData\Local\Programs\Python\Python311\Lib\site-packages\django\core\handlers\exception.py", line 55, in inner
    response = get_response(request)
               ^^^^^^^^^^^^^^^^^^^^^
  File "C:\Users\86135\AppData\Local\Programs\Python\Python311\Lib\site-packages\django\core\handlers\base.py", line 197, in _get_response
    response = wrapped_callback(request, *callback_args, **callback_kwargs)
               ^^^^^^^^^^^^^^^^^^^^^^^^^^^^^^^^^^^^^^^^^^^^^^^^^^^^^^^^^^^^
  File "C:\Users\86135\AppData\Local\Programs\Python\Python311\Lib\site-packages\django\views\decorators\csrf.py", line 56, in wrapper_view
    return view_func(*args, **kwargs)
           ^^^^^^^^^^^^^^^^^^^^^^^^^^
  File "C:\Users\86135\AppData\Local\Programs\Python\Python311\Lib\site-packages\django\views\generic\base.py", line 104, in view
    return self.dispatch(request, *args, **kwargs)
           ^^^^^^^^^^^^^^^^^^^^^^^^^^^^^^^^^^^^^^^
  File "C:\Users\86135\AppData\Local\Programs\Python\Python311\Lib\site-packages\rest_framework\views.py", line 511, in dispatch
    self.response = self.finalize_response(request, response, *args, **kwargs)
                    ^^^^^^^^^^^^^^^^^^^^^^^^^^^^^^^^^^^^^^^^^^^^^^^^^^^^^^^^^^
  File "C:\Users\86135\AppData\Local\Programs\Python\Python311\Lib\site-packages\rest_framework\views.py", line 423, in finalize_response
    assert isinstance(response, HttpResponseBase), (
AssertionError: Expected a `Response`, `HttpResponse` or `HttpStreamingResponse` to be returned from the view, but received a `<class 'NoneType'>`
[2024-01-26 14:43:22,926][Thread-2 (process_request_thread):50860][task_id:django.request][log.py:241][ERROR][Internal Server Error: /api/tree/178]
Traceback (most recent call last):
  File "C:\Users\86135\AppData\Local\Programs\Python\Python311\Lib\site-packages\django\core\handlers\exception.py", line 55, in inner
    response = get_response(request)
               ^^^^^^^^^^^^^^^^^^^^^
  File "C:\Users\86135\AppData\Local\Programs\Python\Python311\Lib\site-packages\django\core\handlers\base.py", line 197, in _get_response
    response = wrapped_callback(request, *callback_args, **callback_kwargs)
               ^^^^^^^^^^^^^^^^^^^^^^^^^^^^^^^^^^^^^^^^^^^^^^^^^^^^^^^^^^^^
  File "C:\Users\86135\AppData\Local\Programs\Python\Python311\Lib\site-packages\django\views\decorators\csrf.py", line 56, in wrapper_view
    return view_func(*args, **kwargs)
           ^^^^^^^^^^^^^^^^^^^^^^^^^^
  File "C:\Users\86135\AppData\Local\Programs\Python\Python311\Lib\site-packages\django\views\generic\base.py", line 104, in view
    return self.dispatch(request, *args, **kwargs)
           ^^^^^^^^^^^^^^^^^^^^^^^^^^^^^^^^^^^^^^^
  File "C:\Users\86135\AppData\Local\Programs\Python\Python311\Lib\site-packages\rest_framework\views.py", line 511, in dispatch
    self.response = self.finalize_response(request, response, *args, **kwargs)
                    ^^^^^^^^^^^^^^^^^^^^^^^^^^^^^^^^^^^^^^^^^^^^^^^^^^^^^^^^^^
  File "C:\Users\86135\AppData\Local\Programs\Python\Python311\Lib\site-packages\rest_framework\views.py", line 423, in finalize_response
    assert isinstance(response, HttpResponseBase), (
AssertionError: Expected a `Response`, `HttpResponse` or `HttpStreamingResponse` to be returned from the view, but received a `<class 'NoneType'>`
[2024-01-26 14:43:31,776][Thread-2 (process_request_thread):50860][task_id:django.request][log.py:241][ERROR][Internal Server Error: /api/tree/158]
Traceback (most recent call last):
  File "C:\Users\86135\AppData\Local\Programs\Python\Python311\Lib\site-packages\django\core\handlers\exception.py", line 55, in inner
    response = get_response(request)
               ^^^^^^^^^^^^^^^^^^^^^
  File "C:\Users\86135\AppData\Local\Programs\Python\Python311\Lib\site-packages\django\core\handlers\base.py", line 197, in _get_response
    response = wrapped_callback(request, *callback_args, **callback_kwargs)
               ^^^^^^^^^^^^^^^^^^^^^^^^^^^^^^^^^^^^^^^^^^^^^^^^^^^^^^^^^^^^
  File "C:\Users\86135\AppData\Local\Programs\Python\Python311\Lib\site-packages\django\views\decorators\csrf.py", line 56, in wrapper_view
    return view_func(*args, **kwargs)
           ^^^^^^^^^^^^^^^^^^^^^^^^^^
  File "C:\Users\86135\AppData\Local\Programs\Python\Python311\Lib\site-packages\django\views\generic\base.py", line 104, in view
    return self.dispatch(request, *args, **kwargs)
           ^^^^^^^^^^^^^^^^^^^^^^^^^^^^^^^^^^^^^^^
  File "C:\Users\86135\AppData\Local\Programs\Python\Python311\Lib\site-packages\rest_framework\views.py", line 511, in dispatch
    self.response = self.finalize_response(request, response, *args, **kwargs)
                    ^^^^^^^^^^^^^^^^^^^^^^^^^^^^^^^^^^^^^^^^^^^^^^^^^^^^^^^^^^
  File "C:\Users\86135\AppData\Local\Programs\Python\Python311\Lib\site-packages\rest_framework\views.py", line 423, in finalize_response
    assert isinstance(response, HttpResponseBase), (
AssertionError: Expected a `Response`, `HttpResponse` or `HttpStreamingResponse` to be returned from the view, but received a `<class 'NoneType'>`
