INFO     [2024-09-27 15:53:17,116] [none] django.utils.autoreload: Watching for file changes with StatReloader
ERROR    [2024-09-27 15:54:47,955] [de69c01dbb4e4352bd34d972a903bb65] django.security.SuspiciousFileOperation: The joined path (C:\Users\86135\Desktop\EasyPost\backend\api\templates\media\default.png) is located outside of the base path component (C:\Users\86135\Desktop\EasyPost\unit-backend\api\templates\media)
Traceback (most recent call last):
  File "C:\Users\86135\AppData\Local\Programs\Python\Python311\Lib\site-packages\asgiref\sync.py", line 534, in thread_handler
    raise exc_info[1]
  File "C:\Users\86135\AppData\Local\Programs\Python\Python311\Lib\site-packages\django\core\handlers\exception.py", line 42, in inner
    response = await get_response(request)
               ^^^^^^^^^^^^^^^^^^^^^^^^^^^
  File "C:\Users\86135\AppData\Local\Programs\Python\Python311\Lib\site-packages\asgiref\sync.py", line 534, in thread_handler
    raise exc_info[1]
  File "C:\Users\86135\AppData\Local\Programs\Python\Python311\Lib\site-packages\django\core\handlers\base.py", line 253, in _get_response_async
    response = await wrapped_callback(
               ^^^^^^^^^^^^^^^^^^^^^^^
  File "C:\Users\86135\AppData\Local\Programs\Python\Python311\Lib\site-packages\asgiref\sync.py", line 479, in __call__
    ret: _R = await loop.run_in_executor(
              ^^^^^^^^^^^^^^^^^^^^^^^^^^^
  File "C:\Users\86135\AppData\Local\Programs\Python\Python311\Lib\concurrent\futures\thread.py", line 58, in run
    result = self.fn(*self.args, **self.kwargs)
             ^^^^^^^^^^^^^^^^^^^^^^^^^^^^^^^^^^
  File "C:\Users\86135\AppData\Local\Programs\Python\Python311\Lib\site-packages\asgiref\sync.py", line 538, in thread_handler
    return func(*args, **kwargs)
           ^^^^^^^^^^^^^^^^^^^^^
  File "C:\Users\86135\AppData\Local\Programs\Python\Python311\Lib\site-packages\django\views\static.py", line 45, in serve
    fullpath = Path(safe_join(document_root, path))
                    ^^^^^^^^^^^^^^^^^^^^^^^^^^^^^^
  File "C:\Users\86135\AppData\Local\Programs\Python\Python311\Lib\site-packages\django\utils\_os.py", line 31, in safe_join
    raise SuspiciousFileOperation(
django.core.exceptions.SuspiciousFileOperation: The joined path (C:\Users\86135\Desktop\EasyPost\backend\api\templates\media\default.png) is located outside of the base path component (C:\Users\86135\Desktop\EasyPost\unit-backend\api\templates\media)
WARNING  [2024-09-27 15:54:47,979] [067f8765079e4badabfea2914fc35c00] django.request: Not Found: /media/C:/Users/86135/Desktop/EasyPost/unit-backend/api/templates/media/default.png
WARNING  [2024-09-27 15:54:48,069] [de69c01dbb4e4352bd34d972a903bb65] django.request: Bad Request: /media/C:/Users/86135/Desktop/EasyPost/backend/api/templates/media/default.png
INFO     [2024-09-27 15:55:45,605] [none] django.utils.autoreload: Watching for file changes with StatReloader
ERROR    [2024-09-27 16:58:08,361] [2687d50bb88b479b8e9737e6e8dff794] django.security.SuspiciousFileOperation: The joined path (C:\Users\86135\Desktop\EasyPost\backend\api\templates\media\default.png) is located outside of the base path component (C:\Users\86135\Desktop\EasyPost\unit-backend\api\templates\media)
Traceback (most recent call last):
  File "C:\Users\86135\AppData\Local\Programs\Python\Python311\Lib\site-packages\asgiref\sync.py", line 534, in thread_handler
    raise exc_info[1]
  File "C:\Users\86135\AppData\Local\Programs\Python\Python311\Lib\site-packages\django\core\handlers\exception.py", line 42, in inner
    response = await get_response(request)
               ^^^^^^^^^^^^^^^^^^^^^^^^^^^
  File "C:\Users\86135\AppData\Local\Programs\Python\Python311\Lib\site-packages\asgiref\sync.py", line 534, in thread_handler
    raise exc_info[1]
  File "C:\Users\86135\AppData\Local\Programs\Python\Python311\Lib\site-packages\django\core\handlers\base.py", line 253, in _get_response_async
    response = await wrapped_callback(
               ^^^^^^^^^^^^^^^^^^^^^^^
  File "C:\Users\86135\AppData\Local\Programs\Python\Python311\Lib\site-packages\asgiref\sync.py", line 479, in __call__
    ret: _R = await loop.run_in_executor(
              ^^^^^^^^^^^^^^^^^^^^^^^^^^^
  File "C:\Users\86135\AppData\Local\Programs\Python\Python311\Lib\concurrent\futures\thread.py", line 58, in run
    result = self.fn(*self.args, **self.kwargs)
             ^^^^^^^^^^^^^^^^^^^^^^^^^^^^^^^^^^
  File "C:\Users\86135\AppData\Local\Programs\Python\Python311\Lib\site-packages\asgiref\sync.py", line 538, in thread_handler
    return func(*args, **kwargs)
           ^^^^^^^^^^^^^^^^^^^^^
  File "C:\Users\86135\AppData\Local\Programs\Python\Python311\Lib\site-packages\django\views\static.py", line 45, in serve
    fullpath = Path(safe_join(document_root, path))
                    ^^^^^^^^^^^^^^^^^^^^^^^^^^^^^^
  File "C:\Users\86135\AppData\Local\Programs\Python\Python311\Lib\site-packages\django\utils\_os.py", line 31, in safe_join
    raise SuspiciousFileOperation(
django.core.exceptions.SuspiciousFileOperation: The joined path (C:\Users\86135\Desktop\EasyPost\backend\api\templates\media\default.png) is located outside of the base path component (C:\Users\86135\Desktop\EasyPost\unit-backend\api\templates\media)
WARNING  [2024-09-27 16:58:08,390] [6ad61325756346a7a44283724c25600c] django.request: Not Found: /media/C:/Users/86135/Desktop/EasyPost/unit-backend/api/templates/media/default.png
WARNING  [2024-09-27 16:58:08,421] [2687d50bb88b479b8e9737e6e8dff794] django.request: Bad Request: /media/C:/Users/86135/Desktop/EasyPost/backend/api/templates/media/default.png
INFO     [2024-09-27 16:59:57,309] [none] django.utils.autoreload: C:\Users\86135\Desktop\EasyPost\unit-backend\api\dao\https.py changed, reloading.
INFO     [2024-09-27 16:59:58,515] [none] django.utils.autoreload: Watching for file changes with StatReloader
INFO     [2024-09-29 14:42:37,772] [none] django.utils.autoreload: C:\Users\86135\Desktop\EasyPost\unit-backend\api\routers\case.py changed, reloading.
INFO     [2024-09-29 14:42:39,124] [none] django.utils.autoreload: Watching for file changes with StatReloader
ERROR    [2024-09-29 15:18:17,826] [aba82b8641c3444295c3e888bc1ebfba] django.security.SuspiciousFileOperation: The joined path (C:\Users\86135\Desktop\EasyPost\backend\api\templates\media\default.png) is located outside of the base path component (C:\Users\86135\Desktop\EasyPost\unit-backend\api\templates\media)
Traceback (most recent call last):
  File "C:\Users\86135\AppData\Local\Programs\Python\Python311\Lib\site-packages\asgiref\sync.py", line 534, in thread_handler
    raise exc_info[1]
  File "C:\Users\86135\AppData\Local\Programs\Python\Python311\Lib\site-packages\django\core\handlers\exception.py", line 42, in inner
    response = await get_response(request)
               ^^^^^^^^^^^^^^^^^^^^^^^^^^^
  File "C:\Users\86135\AppData\Local\Programs\Python\Python311\Lib\site-packages\asgiref\sync.py", line 534, in thread_handler
    raise exc_info[1]
  File "C:\Users\86135\AppData\Local\Programs\Python\Python311\Lib\site-packages\django\core\handlers\base.py", line 253, in _get_response_async
    response = await wrapped_callback(
               ^^^^^^^^^^^^^^^^^^^^^^^
  File "C:\Users\86135\AppData\Local\Programs\Python\Python311\Lib\site-packages\asgiref\sync.py", line 479, in __call__
    ret: _R = await loop.run_in_executor(
              ^^^^^^^^^^^^^^^^^^^^^^^^^^^
  File "C:\Users\86135\AppData\Local\Programs\Python\Python311\Lib\concurrent\futures\thread.py", line 58, in run
    result = self.fn(*self.args, **self.kwargs)
             ^^^^^^^^^^^^^^^^^^^^^^^^^^^^^^^^^^
  File "C:\Users\86135\AppData\Local\Programs\Python\Python311\Lib\site-packages\asgiref\sync.py", line 538, in thread_handler
    return func(*args, **kwargs)
           ^^^^^^^^^^^^^^^^^^^^^
  File "C:\Users\86135\AppData\Local\Programs\Python\Python311\Lib\site-packages\django\views\static.py", line 45, in serve
    fullpath = Path(safe_join(document_root, path))
                    ^^^^^^^^^^^^^^^^^^^^^^^^^^^^^^
  File "C:\Users\86135\AppData\Local\Programs\Python\Python311\Lib\site-packages\django\utils\_os.py", line 31, in safe_join
    raise SuspiciousFileOperation(
django.core.exceptions.SuspiciousFileOperation: The joined path (C:\Users\86135\Desktop\EasyPost\backend\api\templates\media\default.png) is located outside of the base path component (C:\Users\86135\Desktop\EasyPost\unit-backend\api\templates\media)
WARNING  [2024-09-29 15:18:17,834] [0c4b19f89e4e4f638d82f1f33f636370] django.request: Not Found: /media/C:/Users/86135/Desktop/EasyPost/unit-backend/api/templates/media/default.png
WARNING  [2024-09-29 15:18:17,870] [aba82b8641c3444295c3e888bc1ebfba] django.request: Bad Request: /media/C:/Users/86135/Desktop/EasyPost/backend/api/templates/media/default.png
ERROR    [2024-09-29 15:21:09,671] [ab57d2e8b2084a0ea66dd99d4d2d853a] django.security.SuspiciousFileOperation: The joined path (C:\Users\86135\Desktop\EasyPost\backend\api\templates\media\default.png) is located outside of the base path component (C:\Users\86135\Desktop\EasyPost\unit-backend\api\templates\media)
Traceback (most recent call last):
  File "C:\Users\86135\AppData\Local\Programs\Python\Python311\Lib\site-packages\asgiref\sync.py", line 534, in thread_handler
    raise exc_info[1]
  File "C:\Users\86135\AppData\Local\Programs\Python\Python311\Lib\site-packages\django\core\handlers\exception.py", line 42, in inner
    response = await get_response(request)
               ^^^^^^^^^^^^^^^^^^^^^^^^^^^
  File "C:\Users\86135\AppData\Local\Programs\Python\Python311\Lib\site-packages\asgiref\sync.py", line 534, in thread_handler
    raise exc_info[1]
  File "C:\Users\86135\AppData\Local\Programs\Python\Python311\Lib\site-packages\django\core\handlers\base.py", line 253, in _get_response_async
    response = await wrapped_callback(
               ^^^^^^^^^^^^^^^^^^^^^^^
  File "C:\Users\86135\AppData\Local\Programs\Python\Python311\Lib\site-packages\asgiref\sync.py", line 479, in __call__
    ret: _R = await loop.run_in_executor(
              ^^^^^^^^^^^^^^^^^^^^^^^^^^^
  File "C:\Users\86135\AppData\Local\Programs\Python\Python311\Lib\concurrent\futures\thread.py", line 58, in run
    result = self.fn(*self.args, **self.kwargs)
             ^^^^^^^^^^^^^^^^^^^^^^^^^^^^^^^^^^
  File "C:\Users\86135\AppData\Local\Programs\Python\Python311\Lib\site-packages\asgiref\sync.py", line 538, in thread_handler
    return func(*args, **kwargs)
           ^^^^^^^^^^^^^^^^^^^^^
  File "C:\Users\86135\AppData\Local\Programs\Python\Python311\Lib\site-packages\django\views\static.py", line 45, in serve
    fullpath = Path(safe_join(document_root, path))
                    ^^^^^^^^^^^^^^^^^^^^^^^^^^^^^^
  File "C:\Users\86135\AppData\Local\Programs\Python\Python311\Lib\site-packages\django\utils\_os.py", line 31, in safe_join
    raise SuspiciousFileOperation(
django.core.exceptions.SuspiciousFileOperation: The joined path (C:\Users\86135\Desktop\EasyPost\backend\api\templates\media\default.png) is located outside of the base path component (C:\Users\86135\Desktop\EasyPost\unit-backend\api\templates\media)
WARNING  [2024-09-29 15:21:09,690] [bb7df0740a0e4edcb213e12285c041bd] django.request: Not Found: /media/C:/Users/86135/Desktop/EasyPost/unit-backend/api/templates/media/default.png
WARNING  [2024-09-29 15:21:09,702] [ab57d2e8b2084a0ea66dd99d4d2d853a] django.request: Bad Request: /media/C:/Users/86135/Desktop/EasyPost/backend/api/templates/media/default.png
INFO     [2024-09-30 10:53:47,869] [none] django.utils.autoreload: C:\Users\86135\Desktop\EasyPost\unit-backend\api\models\https.py changed, reloading.
INFO     [2024-09-30 10:53:49,728] [none] django.utils.autoreload: Watching for file changes with StatReloader
